Workbook

Sheet TH1_Đất sẵn có 1
A1: XỬ LÝ ĐẤT ĐAI TRONG THẨM ĐỊNH DỰ ÁN
A2: Trường hợp 1: Đất sẵn có, định giá theo thị trường (Theo Harberger & Jenkins 1995; Jenkins et al. 2011)
A3: (Các trường hợp tương đương: Đất có sẵn (định giá tại năm 0 là 10 tỷ), Đất mua tại năm 0 với giá 10 tỷ
A5: THÔNG SỐ DỰ ÁN (ĐV: TRIỆU ĐỒNG)
A6: Đầu tư | C6: Doanh thu & chi phí hoạt động | F6: Thông tin khác
A7: Đất (sẵn có) | B7: 10000 | C7: Chi phí cố định | D7: 1200 | F7: Lạm phát | G7: 0.05
A8: Xây dựng | B8: 30000 | C8: Chi phí biến đổi | D8: 0.2 | E8: /Doanh thu | F8: Thuế TNDN | G8: 0.2
A9: Thiết bị | B9: 20000 | C9: Doanh thu | D9: 9000 | F9: re thực | G9: 0.1
A10: Tài trợ | C10: Tỷ lệ tăng doanh thu | D10: 0.03 | E10: /năm | F10: re danh nghĩa | G10: =G9+G7+G9*G7 -> 0.155
A11: Vay ngân hàng | B11: =70%*(B8+B9) -> 35000 | C11: Vốn lưu động | F11: WACC | G11: =0.7*B13+0.3*G10 -> 0.11825
A12: Lãi suất thực | B12: 0.05 | C12: AR | D12: 0.1 | E12: /Doanh thu | F12: VAT | G12: 0
A13: Lãi suất danh nghĩa | B13: =B12+G7+B12*G7 -> 0.1025 | C13: AP | D13: 0.1 | E13: /Chi phí biến đổi | F13: Khấu hao | G13: 20
A14: Số năm trả nợ | B14: 10 | C14: CB | D14: 0.05 | E14: /Doanh thu | F14: Vòng đời dự án | G14: 20
A16: CHỈ SỐ GIÁ
A17: Năm | B17: 0 | C17: 1 | D17: 2 | E17: 3 | F17: 4 | G17: 5 | H17: 6 | I17: 7 | J17: 8 | K17: 9 | L17: 10 | M17: 11 | N17: 12 | O17: 13 | P17: 14 | Q17: 15 | R17: 16 | S17: 17 | T17: 18 | U17: 19 | V17: 20
A18: Chỉ số lạm phát | C18: =(1+$G$7)^C17 -> 1.05 | D18: =(1+$G$7)^D17 -> 1.1025 | E18: =(1+$G$7)^E17 -> 1.157625 | F18: =(1+$G$7)^F17 -> 1.2155063 | G18: =(1+$G$7)^G17 -> 1.2762816 | H18: =(1+$G$7)^H17 -> 1.3400956 | I18: =(1+$G$7)^I17 -> 1.4071004 | J18: =(1+$G$7)^J17 -> 1.4774554 | ... V18: =(1+$G$7)^V17 -> 2.6532977
A19: Chỉ số tăng doanh thu | C19: =(1+$D$10)^C17 -> 1.03 | D19: =(1+$D$10)^D17 -> 1.0609 | E19: =(1+$D$10)^E17 -> 1.092727 | F19: =(1+$D$10)^F17 -> 1.1255088 | G19: =(1+$D$10)^G17 -> 1.1592741 | H19: =(1+$D$10)^H17 -> 1.1940523 | I19: =(1+$D$10)^I17 -> 1.2298739 | J19: =(1+$D$10)^J17 -> 1.2667701 | ... V19: =(1+$D$10)^V17 -> 1.8061112
A21: DOANH THU, CHI PHÍ
A22: Năm | B22: 0 | C22: 1 | D22: 2 | E22: 3 | F22: 4 | G22: 5 | H22: 6 | I22: 7 | J22: 8 | K22: 9 | L22: 10 | M22: 11 | N22: 12 | O22: 13 | P22: 14 | Q22: 15 | R22: 16 | S22: 17 | T22: 18 | U22: 19 | V22: 20
A23: Doanh thu
A24: Chi phí cố định | C24: =$D$7 -> 1200 | D24: =$D$7 -> 1200 | E24: =$D$7*$D$18 -> 1323 | F24: =$D$7*$D$18 -> 1323 | G24: =$D$7*$F$18 -> 1458.6075 | H24: =$D$7*$F$18 -> 1458.6075 | I24: =$D$7*$H$18 -> 1608.1148 | J24: =$D$7*$H$18 -> 1608.1148 | K24: =$D$7*$J$18 -> 1772.9465 | L24: =$D$7*$J$18 -> 1772.9465 | M24: =$D$7*$L$18 -> 1954.6736 | N24: =$D$7*$L$18 -> 1954.6736 | O24: =$D$7*$N$18 -> 2155.0276 | P24: =$D$7*$N$18 -> 2155.0276 | Q24: =$D$7*$P$18 -> 2375.9179 | R24: =$D$7*$P$18 -> 2375.9179 | S24: =$D$7*$R$18 -> 2619.4495 | T24: =$D$7*$R$18 -> 2619.4495 | U24: =$D$7*$T$18 -> 2887.9431 | V24: =$D$7*$T$18 -> 2887.9431
A25: Chi phí biến đổi | C25: =C23*$D$8 -> 0 | D25: =D23*$D$8 -> 0 | E25: =E23*$D$8 -> 0 | F25: =F23*$D$8 -> 0 | G25: =G23*$D$8 -> 0 | H25: =H23*$D$8 -> 0 | I25: =I23*$D$8 -> 0 | J25: =J23*$D$8 -> 0 | ... V25: =V23*$D$8 -> 0
A27: THUẾ THU NHẬP DOANH NGHIỆP
A28: Năm | B28: 0 | C28: 1 | D28: 2 | E28: 3 | F28: 4 | G28: 5 | H28: 6 | I28: 7 | J28: 8 | K28: 9 | L28: 10 | M28: 11 | N28: 12 | O28: 13 | P28: 14 | Q28: 15 | R28: 16 | S28: 17 | T28: 18 | U28: 19 | V28: 20
A29: Doanh thu | C29: =C23 -> 0 | D29: =D23 -> 0 | E29: =E23 -> 0 | F29: =F23 -> 0 | G29: =G23 -> 0 | H29: =H23 -> 0 | I29: =I23 -> 0 | J29: =J23 -> 0 | ... V29: =V23 -> 0
A30: Chi phí hoạt động | C30: =C24+C25 -> 1200 | D30: =D24+D25 -> 1200 | E30: =E24+E25 -> 1323 | F30: =F24+F25 -> 1323 | G30: =G24+G25 -> 1458.6075 | H30: =H24+H25 -> 1458.6075 | I30: =I24+I25 -> 1608.1148 | J30: =J24+J25 -> 1608.1148 | ... V30: =V24+V25 -> 2887.9431
A31: Khấu hao tài sản | C31: =($B$8+$B$9)/$G$13 -> 2500 | D31: =($B$8+$B$9)/$G$13 -> 2500 | E31: =($B$8+$B$9)/$G$13 -> 2500 | F31: =($B$8+$B$9)/$G$13 -> 2500 | G31: =($B$8+$B$9)/$G$13 -> 2500 | H31: =($B$8+$B$9)/$G$13 -> 2500 | I31: =($B$8+$B$9)/$G$13 -> 2500 | J31: =($B$8+$B$9)/$G$13 -> 2500 | ... V31: =($B$8+$B$9)/$G$13 -> 2500
A32: EBIT | C32: =C29-C30-C31 -> -3700 | D32: =D29-D30-D31 -> -3700 | E32: =E29-E30-E31 -> -3823 | F32: =F29-F30-F31 -> -3823 | G32: =G29-G30-G31 -> -3958.6075 | H32: =H29-H30-H31 -> -3958.6075 | I32: =I29-I30-I31 -> -4108.1148 | J32: =J29-J30-J31 -> -4108.1148 | ... V32: =V29-V30-V31 -> -5387.9431
A33: Trả lãi vay
A34: EBT | C34: =C32-C33 -> -3700 | D34: =D32-D33 -> -3700 | E34: =E32-E33 -> -3823 | F34: =F32-F33 -> -3823 | G34: =G32-G33 -> -3958.6075 | H34: =H32-H33 -> -3958.6075 | I34: =I32-I33 -> -4108.1148 | J34: =J32-J33 -> -4108.1148 | ... V34: =V32-V33 -> -5387.9431
A35: Thuế TNDN | C35: =C34*$G$8 -> -740 | D35: =D34*$G$8 -> -740 | E35: =E34*$G$8 -> -764.6 | F35: =F34*$G$8 -> -764.6 | G35: =G34*$G$8 -> -791.7215 | H35: =H34*$G$8 -> -791.7215 | I35: =I34*$G$8 -> -821.62295 | J35: =J34*$G$8 -> -821.62295 | ... V35: =V34*$G$8 -> -1077.5886
A37: VỐN LƯU ĐỘNG
A38: Năm | B38: 0 | C38: 1 | D38: 2 | E38: 3 | F38: 4 | G38: 5 | H38: 6 | I38: 7 | J38: 8 | K38: 9 | L38: 10 | M38: 11 | N38: 12 | O38: 13 | P38: 14 | Q38: 15 | R38: 16 | S38: 17 | T38: 18 | U38: 19 | V38: 20
A39: AR | C39: =C23*$D$12 -> 0 | D39: =D23*$D$12 -> 0 | E39: =E23*$D$12 -> 0 | F39: =F23*$D$12 -> 0 | G39: =G23*$D$12 -> 0 | H39: =H23*$D$12 -> 0 | I39: =I23*$D$12 -> 0 | J39: =J23*$D$12 -> 0 | ... U39: =U23*$D$12 -> 0
A40: AP | C40: =$D$13*C25 -> 0 | D40: =$D$13*D25 -> 0 | E40: =$D$13*E25 -> 0 | F40: =$D$13*F25 -> 0 | G40: =$D$13*G25 -> 0 | H40: =$D$13*H25 -> 0 | I40: =$D$13*I25 -> 0 | J40: =$D$13*J25 -> 0 | ... U40: =$D$13*U25 -> 0
A41: CB | C41: =C29*$D$14 -> 0 | D41: =D29*$D$14 -> 0 | E41: =E29*$D$14 -> 0 | F41: =F29*$D$14 -> 0 | G41: =G29*$D$14 -> 0 | H41: =H29*$D$14 -> 0 | I41: =I29*$D$14 -> 0 | J41: =J29*$D$14 -> 0 | ... U41: =U29*$D$14 -> 0
A42: DAR | C42: =B39-C39 -> 0 | D42: =C39-D39 -> 0 | E42: =D39-E39 -> 0 | F42: =E39-F39 -> 0 | G42: =F39-G39 -> 0 | H42: =G39-H39 -> 0 | I42: =H39-I39 -> 0 | J42: =I39-J39 -> 0 | ... V42: =U39-V39 -> 0
A43: DAP | C43: =B40-C40 -> 0 | D43: =C40-D40 -> 0 | E43: =D40-E40 -> 0 | F43: =E40-F40 -> 0 | G43: =F40-G40 -> 0 | H43: =G40-H40 -> 0 | I43: =H40-I40 -> 0 | J43: =I40-J40 -> 0 | ... V43: =U40-V40 -> 0
A44: DCB | C44: =C41-B41 -> 0 | D44: =D41-C41 -> 0 | E44: =E41-D41 -> 0 | F44: =F41-E41 -> 0 | G44: =G41-F41 -> 0 | H44: =H41-G41 -> 0 | I44: =I41-H41 -> 0 | J44: =J41-I41 -> 0 | ... V44: =V41-U41 -> 0
A46: BÁO CÁO NGÂN LƯU TIPV
...

Sheet TH2_Đất sẵn có 2
A1: XỬ LÝ ĐẤT ĐAI TRONG THẨM ĐỊNH DỰ ÁN
A2: Trường hợp 2: Đất sẵn có, không đưa vào tính (theo cách làm của nhiều doanh nghiệp Việt Nam)
A3: (Các trường hợp tương đương: Đất có sẵn (định giá tại năm 0 là 10 tỷ), Đất mua tại năm 0 với giá 10 tỷ
A5: THÔNG SỐ DỰ ÁN (ĐV: TRIỆU ĐỒNG)
A6: Đầu tư | C6: Doanh thu & chi phí hoạt động | F6: Thông tin khác
A7: Đất (sẵn có) | B7: 0 | C7: Chi phí cố định | D7: 1200 | F7: Lạm phát | G7: 0.05
A8: Xây dựng | B8: 30000 | C8: Chi phí biến đổi | D8: 0.2 | E8: /Doanh thu | F8: Thuế TNDN | G8: 0.2
A9: Thiết bị | B9: 20000 | C9: Doanh thu | D9: 9000 | F9: re thực | G9: 0.1
A10: Tài trợ | C10: Tỷ lệ tăng doanh thu | D10: 0.03 | E10: /năm | F10: re danh nghĩa | G10: =G9+G7+G9*G7 -> 0.155
A11: Vay ngân hàng | B11: =70%*(B8+B9) -> 35000 | C11: Vốn lưu động | F11: WACC | G11: =0.7*B13+0.3*G10 -> 0.11825
A12: Lãi suất thực | B12: 0.05 | C12: AR | D12: 0.1 | E12: /Doanh thu | F12: VAT | G12: 0
A13: Lãi suất danh nghĩa | B13: =B12+G7+B12*G7 -> 0.1025 | C13: AP | D13: 0.1 | E13: /Chi phí biến đổi | F13: Khấu hao | G13: 20
A14: Số năm trả nợ | B14: 10 | C14: CB | D14: 0.05 | E14: /Doanh thu | F14: Vòng đời dự án | G14: 20
A16: CHỈ SỐ GIÁ
A17: Năm | B17: 0 | C17: 1 | D17: 2 | E17: 3 | F17: 4 | G17: 5 | H17: 6 | I17: 7 | J17: 8 | K17: 9 | L17: 10 | M17: 11 | N17: 12 | O17: 13 | P17: 14 | Q17: 15 | R17: 16 | S17: 17 | T17: 18 | U17: 19 | V17: 20
A18: Chỉ số lạm phát | C18: =(1+$G$7)^C17 -> 1.05 | D18: =(1+$G$7)^D17 -> 1.1025 | E18: =(1+$G$7)^E17 -> 1.157625 | F18: =(1+$G$7)^F17 -> 1.2155063 | G18: =(1+$G$7)^G17 -> 1.2762816 | H18: =(1+$G$7)^H17 -> 1.3400956 | I18: =(1+$G$7)^I17 -> 1.4071004 | J18: =(1+$G$7)^J17 -> 1.4774554 | ... V18: =(1+$G$7)^V17 -> 2.6532977
A19: Chỉ số tăng doanh thu | C19: =(1+$D$10)^C17 -> 1.03 | D19: =(1+$D$10)^D17 -> 1.0609 | E19: =(1+$D$10)^E17 -> 1.092727 | F19: =(1+$D$10)^F17 -> 1.1255088 | G19: =(1+$D$10)^G17 -> 1.1592741 | H19: =(1+$D$10)^H17 -> 1.1940523 | I19: =(1+$D$10)^I17 -> 1.2298739 | J19: =(1+$D$10)^J17 -> 1.2667701 | ... V19: =(1+$D$10)^V17 -> 1.8061112
A21: DOANH THU, CHI PHÍ
A22: Năm | B22: 0 | C22: 1 | D22: 2 | E22: 3 | F22: 4 | G22: 5 | H22: 6 | I22: 7 | J22: 8 | K22: 9 | L22: 10 | M22: 11 | N22: 12 | O22: 13 | P22: 14 | Q22: 15 | R22: 16 | S22: 17 | T22: 18 | U22: 19 | V22: 20
A23: Doanh thu
A24: Chi phí cố định | C24: =$D$7 -> 1200 | D24: =$D$7 -> 1200 | E24: =$D$7*$D$18 -> 1323 | F24: =$D$7*$D$18 -> 1323 | G24: =$D$7*$F$18 -> 1458.6075 | H24: =$D$7*$F$18 -> 1458.6075 | I24: =$D$7*$H$18 -> 1608.1148 | J24: =$D$7*$H$18 -> 1608.1148 | K24: =$D$7*$J$18 -> 1772.9465 | L24: =$D$7*$J$18 -> 1772.9465 | M24: =$D$7*$L$18 -> 1954.6736 | N24: =$D$7*$L$18 -> 1954.6736 | O24: =$D$7*$N$18 -> 2155.0276 | P24: =$D$7*$N$18 -> 2155.0276 | Q24: =$D$7*$P$18 -> 2375.9179 | R24: =$D$7*$P$18 -> 2375.9179 | S24: =$D$7*$R$18 -> 2619.4495 | T24: =$D$7*$R$18 -> 2619.4495 | U24: =$D$7*$T$18 -> 2887.9431 | V24: =$D$7*$T$18 -> 2887.9431
A25: Chi phí biến đổi | C25: =C23*$D$8 -> 0 | D25: =D23*$D$8 -> 0 | E25: =E23*$D$8 -> 0 | F25: =F23*$D$8 -> 0 | G25: =G23*$D$8 -> 0 | H25: =H23*$D$8 -> 0 | I25: =I23*$D$8 -> 0 | J25: =J23*$D$8 -> 0 | ... V25: =V23*$D$8 -> 0
A27: THUẾ THU NHẬP DOANH NGHIỆP
A28: Năm | B28: 0 | C28: 1 | D28: 2 | E28: 3 | F28: 4 | G28: 5 | H28: 6 | I28: 7 | J28: 8 | K28: 9 | L28: 10 | M28: 11 | N28: 12 | O28: 13 | P28: 14 | Q28: 15 | R28: 16 | S28: 17 | T28: 18 | U28: 19 | V28: 20
A29: Doanh thu | C29: =C23 -> 0 | D29: =D23 -> 0 | E29: =E23 -> 0 | F29: =F23 -> 0 | G29: =G23 -> 0 | H29: =H23 -> 0 | I29: =I23 -> 0 | J29: =J23 -> 0 | ... V29: =V23 -> 0
A30: Chi phí hoạt động | C30: =C24+C25 -> 1200 | D30: =D24+D25 -> 1200 | E30: =E24+E25 -> 1323 | F30: =F24+F25 -> 1323 | G30: =G24+G25 -> 1458.6075 | H30: =H24+H25 -> 1458.6075 | I30: =I24+I25 -> 1608.1148 | J30: =J24+J25 -> 1608.1148 | ... V30: =V24+V25 -> 2887.9431
A31: Khấu hao tài sản | C31: =($B$8+$B$9)/$G$13 -> 2500 | D31: =($B$8+$B$9)/$G$13 -> 2500 | E31: =($B$8+$B$9)/$G$13 -> 2500 | F31: =($B$8+$B$9)/$G$13 -> 2500 | G31: =($B$8+$B$9)/$G$13 -> 2500 | H31: =($B$8+$B$9)/$G$13 -> 2500 | I31: =($B$8+$B$9)/$G$13 -> 2500 | J31: =($B$8+$B$9)/$G$13 -> 2500 | ... V31: =($B$8+$B$9)/$G$13 -> 2500
A32: EBIT | C32: =C29-C30-C31 -> -3700 | D32: =D29-D30-D31 -> -3700 | E32: =E29-E30-E31 -> -3823 | F32: =F29-F30-F31 -> -3823 | G32: =G29-G30-G31 -> -3958.6075 | H32: =H29-H30-H31 -> -3958.6075 | I32: =I29-I30-I31 -> -4108.1148 | J32: =J29-J30-J31 -> -4108.1148 | ... V32: =V29-V30-V31 -> -5387.9431
A33: Trả lãi vay
A34: EBT | C34: =C32-C33 -> -3700 | D34: =D32-D33 -> -3700 | E34: =E32-E33 -> -3823 | F34: =F32-F33 -> -3823 | G34: =G32-G33 -> -3958.6075 | H34: =H32-H33 -> -3958.6075 | I34: =I32-I33 -> -4108.1148 | J34: =J32-J33 -> -4108.1148 | ... V34: =V32-V33 -> -5387.9431
A35: Thuế TNDN | C35: =C34*$G$8 -> -740 | D35: =D34*$G$8 -> -740 | E35: =E34*$G$8 -> -764.6 | F35: =F34*$G$8 -> -764.6 | G35: =G34*$G$8 -> -791.7215 | H35: =H34*$G$8 -> -791.7215 | I35: =I34*$G$8 -> -821.62295 | J35: =J34*$G$8 -> -821.62295 | ... V35: =V34*$G$8 -> -1077.5886
A37: VỐN LƯU ĐỘNG
A38: Năm | B38: 0 | C38: 1 | D38: 2 | E38: 3 | F38: 4 | G38: 5 | H38: 6 | I38: 7 | J38: 8 | K38: 9 | L38: 10 | M38: 11 | N38: 12 | O38: 13 | P38: 14 | Q38: 15 | R38: 16 | S38: 17 | T38: 18 | U38: 19 | V38: 20
A39: AR | C39: =C23*$D$12 -> 0 | D39: =D23*$D$12 -> 0 | E39: =E23*$D$12 -> 0 | F39: =F23*$D$12 -> 0 | G39: =G23*$D$12 -> 0 | H39: =H23*$D$12 -> 0 | I39: =I23*$D$12 -> 0 | J39: =J23*$D$12 -> 0 | ... U39: =U23*$D$12 -> 0
A40: AP | C40: =$D$13*C25 -> 0 | D40: =$D$13*D25 -> 0 | E40: =$D$13*E25 -> 0 | F40: =$D$13*F25 -> 0 | G40: =$D$13*G25 -> 0 | H40: =$D$13*H25 -> 0 | I40: =$D$13*I25 -> 0 | J40: =$D$13*J25 -> 0 | ... U40: =$D$13*U25 -> 0
A41: CB | C41: =C29*$D$14 -> 0 | D41: =D29*$D$14 -> 0 | E41: =E29*$D$14 -> 0 | F41: =F29*$D$14 -> 0 | G41: =G29*$D$14 -> 0 | H41: =H29*$D$14 -> 0 | I41: =I29*$D$14 -> 0 | J41: =J29*$D$14 -> 0 | ... U41: =U29*$D$14 -> 0
A42: DAR | C42: =B39-C39 -> 0 | D42: =C39-D39 -> 0 | E42: =D39-E39 -> 0 | F42: =E39-F39 -> 0 | G42: =F39-G39 -> 0 | H42: =G39-H39 -> 0 | I42: =H39-I39 -> 0 | J42: =I39-J39 -> 0 | ... V42: =U39-V39 -> 0
A43: DAP | C43: =B40-C40 -> 0 | D43: =C40-D40 -> 0 | E43: =D40-E40 -> 0 | F43: =E40-F40 -> 0 | G43: =F40-G40 -> 0 | H43: =G40-H40 -> 0 | I43: =H40-I40 -> 0 | J43: =I40-J40 -> 0 | ... V43: =U40-V40 -> 0
A44: DCB | C44: =C41-B41 -> 0 | D44: =D41-C41 -> 0 | E44: =E41-D41 -> 0 | F44: =F41-E41 -> 0 | G44: =G41-F41 -> 0 | H44: =H41-G41 -> 0 | I44: =I41-H41 -> 0 | J44: =J41-I41 -> 0 | ... V44: =V41-U41 -> 0
A46: BÁO CÁO NGÂN LƯU TIPV
...

Sheet TH3_Đất thuê 1
A1: XỬ LÝ ĐẤT ĐAI TRONG THẨM ĐỊNH DỰ ÁN
A2: Trường hợp 3: Đất thuê, thanh toán 1 lần vào năm 0
A3: (Các trường hợp tương đương: Đất thuê, Đất giao (dự án chịu chi phí đền bù, giải phóng mặt bằng, và các chi phí liên quan)
A5: THÔNG SỐ DỰ ÁN (ĐV: TRIỆU ĐỒNG)
A6: Đầu tư | C6: Doanh thu & chi phí hoạt động | F6: Thông tin khác
A7: Đất (thuê, thanh toán 1 lần) | B7: 10000 | C7: Chi phí cố định | D7: 1200 | F7: Lạm phát | G7: 0.05
A8: Xây dựng | B8: 30000 | C8: Chi phí biến đổi | D8: 0.2 | E8: /Doanh thu | F8: Thuế TNDN | G8: 0.2
A9: Thiết bị | B9: 20000 | C9: Doanh thu | D9: 9000 | F9: re thực | G9: 0.1
A10: Tài trợ | C10: Tỷ lệ tăng doanh thu | D10: 0.03 | E10: /năm | F10: re danh nghĩa | G10: =G9+G7+G9*G7 -> 0.155
A11: Vay ngân hàng | B11: =70%*(B8+B9) -> 35000 | C11: Vốn lưu động | F11: WACC | G11: =0.7*B13+0.3*G10 -> 0.11825
A12: Lãi suất thực | B12: 0.05 | C12: AR | D12: 0.1 | E12: /Doanh thu | F12: VAT | G12: 0
A13: Lãi suất danh nghĩa | B13: =B12+G7+B12*G7 -> 0.1025 | C13: AP | D13: 0.1 | E13: /Chi phí biến đổi | F13: Khấu hao | G13: 20
A14: Số năm trả nợ | B14: 10 | C14: CB | D14: 0.05 | E14: /Doanh thu | F14: Vòng đời dự án | G14: 20
A16: CHỈ SỐ GIÁ
A17: Năm | B17: 0 | C17: 1 | D17: 2 | E17: 3 | F17: 4 | G17: 5 | H17: 6 | I17: 7 | J17: 8 | K17: 9 | L17: 10 | M17: 11 | N17: 12 | O17: 13 | P17: 14 | Q17: 15 | R17: 16 | S17: 17 | T17: 18 | U17: 19 | V17: 20
A18: Chỉ số lạm phát | C18: =(1+$G$7)^C17 -> 1.05 | D18: =(1+$G$7)^D17 -> 1.1025 | E18: =(1+$G$7)^E17 -> 1.157625 | F18: =(1+$G$7)^F17 -> 1.2155063 | G18: =(1+$G$7)^G17 -> 1.2762816 | H18: =(1+$G$7)^H17 -> 1.3400956 | I18: =(1+$G$7)^I17 -> 1.4071004 | J18: =(1+$G$7)^J17 -> 1.4774554 | ... V18: =(1+$G$7)^V17 -> 2.6532977
A19: Chỉ số tăng doanh thu | C19: =(1+$D$10)^C17 -> 1.03 | D19: =(1+$D$10)^D17 -> 1.0609 | E19: =(1+$D$10)^E17 -> 1.092727 | F19: =(1+$D$10)^F17 -> 1.1255088 | G19: =(1+$D$10)^G17 -> 1.1592741 | H19: =(1+$D$10)^H17 -> 1.1940523 | I19: =(1+$D$10)^I17 -> 1.2298739 | J19: =(1+$D$10)^J17 -> 1.2667701 | ... V19: =(1+$D$10)^V17 -> 1.8061112
A21: DOANH THU, CHI PHÍ
A22: Năm | B22: 0 | C22: 1 | D22: 2 | E22: 3 | F22: 4 | G22: 5 | H22: 6 | I22: 7 | J22: 8 | K22: 9 | L22: 10 | M22: 11 | N22: 12 | O22: 13 | P22: 14 | Q22: 15 | R22: 16 | S22: 17 | T22: 18 | U22: 19 | V22: 20
A23: Doanh thu
A24: Chi phí cố định | C24: =$D$7 -> 1200 | D24: =$D$7 -> 1200 | E24: =$D$7*$D$18 -> 1323 | F24: =$D$7*$D$18 -> 1323 | G24: =$D$7*$F$18 -> 1458.6075 | H24: =$D$7*$F$18 -> 1458.6075 | I24: =$D$7*$H$18 -> 1608.1148 | J24: =$D$7*$H$18 -> 1608.1148 | K24: =$D$7*$J$18 -> 1772.9465 | L24: =$D$7*$J$18 -> 1772.9465 | M24: =$D$7*$L$18 -> 1954.6736 | N24: =$D$7*$L$18 -> 1954.6736 | O24: =$D$7*$N$18 -> 2155.0276 | P24: =$D$7*$N$18 -> 2155.0276 | Q24: =$D$7*$P$18 -> 2375.9179 | R24: =$D$7*$P$18 -> 2375.9179 | S24: =$D$7*$R$18 -> 2619.4495 | T24: =$D$7*$R$18 -> 2619.4495 | U24: =$D$7*$T$18 -> 2887.9431 | V24: =$D$7*$T$18 -> 2887.9431
A25: Chi phí thuê đất (cố định) | C25: =$B$7/$G$14 -> 500 | D25: =$B$7/$G$14 -> 500 | E25: =$B$7/$G$14 -> 500 | F25: =$B$7/$G$14 -> 500 | G25: =$B$7/$G$14 -> 500 | H25: =$B$7/$G$14 -> 500 | I25: =$B$7/$G$14 -> 500 | J25: =$B$7/$G$14 -> 500 | ... V25: =$B$7/$G$14 -> 500
A26: Chi phí biến đổi | C26: =C23*$D$8 -> 0 | D26: =D23*$D$8 -> 0 | E26: =E23*$D$8 -> 0 | F26: =F23*$D$8 -> 0 | G26: =G23*$D$8 -> 0 | H26: =H23*$D$8 -> 0 | I26: =I23*$D$8 -> 0 | J26: =J23*$D$8 -> 0 | ... V26: =V23*$D$8 -> 0
A28: THUẾ THU NHẬP DOANH NGHIỆP
A29: Năm | B29: 0 | C29: 1 | D29: 2 | E29: 3 | F29: 4 | G29: 5 | H29: 6 | I29: 7 | J29: 8 | K29: 9 | L29: 10 | M29: 11 | N29: 12 | O29: 13 | P29: 14 | Q29: 15 | R29: 16 | S29: 17 | T29: 18 | U29: 19 | V29: 20
A30: Doanh thu | C30: =C23 -> 0 | D30: =D23 -> 0 | E30: =E23 -> 0 | F30: =F23 -> 0 | G30: =G23 -> 0 | H30: =H23 -> 0 | I30: =I23 -> 0 | J30: =J23 -> 0 | ... V30: =V23 -> 0
A31: Chi phí hoạt động | C31: =SUM(C24:C26) -> 1700 | D31: =SUM(D24:D26) -> 1700 | E31: =SUM(E24:E26) -> 1823 | F31: =SUM(F24:F26) -> 1823 | G31: =SUM(G24:G26) -> 1958.6075 | H31: =SUM(H24:H26) -> 1958.6075 | I31: =SUM(I24:I26) -> 2108.1148 | J31: =SUM(J24:J26) -> 2108.1148 | ... V31: =SUM(V24:V26) -> 3387.9431
A32: Khấu hao tài sản | C32: =($B$8+$B$9)/$G$13 -> 2500 | D32: =($B$8+$B$9)/$G$13 -> 2500 | E32: =($B$8+$B$9)/$G$13 -> 2500 | F32: =($B$8+$B$9)/$G$13 -> 2500 | G32: =($B$8+$B$9)/$G$13 -> 2500 | H32: =($B$8+$B$9)/$G$13 -> 2500 | I32: =($B$8+$B$9)/$G$13 -> 2500 | J32: =($B$8+$B$9)/$G$13 -> 2500 | ... V32: =($B$8+$B$9)/$G$13 -> 2500
A33: EBIT | C33: =C30-SUM(C31:C32) -> -4200 | D33: =D30-SUM(D31:D32) -> -4200 | E33: =E30-SUM(E31:E32) -> -4323 | F33: =F30-SUM(F31:F32) -> -4323 | G33: =G30-SUM(G31:G32) -> -4458.6075 | H33: =H30-SUM(H31:H32) -> -4458.6075 | I33: =I30-SUM(I31:I32) -> -4608.1148 | J33: =J30-SUM(J31:J32) -> -4608.1148 | ... V33: =V30-SUM(V31:V32) -> -5887.9431
A34: Trả lãi vay
A35: EBT | C35: =C33-C34 -> -4200 | D35: =D33-D34 -> -4200 | E35: =E33-E34 -> -4323 | F35: =F33-F34 -> -4323 | G35: =G33-G34 -> -4458.6075 | H35: =H33-H34 -> -4458.6075 | I35: =I33-I34 -> -4608.1148 | J35: =J33-J34 -> -4608.1148 | ... V35: =V33-V34 -> -5887.9431
A36: Thuế TNDN | C36: =C35*$G$8 -> -840 | D36: =D35*$G$8 -> -840 | E36: =E35*$G$8 -> -864.6 | F36: =F35*$G$8 -> -864.6 | G36: =G35*$G$8 -> -891.7215 | H36: =H35*$G$8 -> -891.7215 | I36: =I35*$G$8 -> -921.62295 | J36: =J35*$G$8 -> -921.62295 | ... V36: =V35*$G$8 -> -1177.5886
A38: VỐN LƯU ĐỘNG
A39: Năm | B39: 0 | C39: 1 | D39: 2 | E39: 3 | F39: 4 | G39: 5 | H39: 6 | I39: 7 | J39: 8 | K39: 9 | L39: 10 | M39: 11 | N39: 12 | O39: 13 | P39: 14 | Q39: 15 | R39: 16 | S39: 17 | T39: 18 | U39: 19 | V39: 20
A40: AR | C40: =C23*$D$12 -> 0 | D40: =D23*$D$12 -> 0 | E40: =E23*$D$12 -> 0 | F40: =F23*$D$12 -> 0 | G40: =G23*$D$12 -> 0 | H40: =H23*$D$12 -> 0 | I40: =I23*$D$12 -> 0 | J40: =J23*$D$12 -> 0 | ... U40: =U23*$D$12 -> 0
A41: AP | C41: =$D$13*C26 -> 0 | D41: =$D$13*D26 -> 0 | E41: =$D$13*E26 -> 0 | F41: =$D$13*F26 -> 0 | G41: =$D$13*G26 -> 0 | H41: =$D$13*H26 -> 0 | I41: =$D$13*I26 -> 0 | J41: =$D$13*J26 -> 0 | ... U41: =$D$13*U26 -> 0
A42: CB | C42: =C30*$D$14 -> 0 | D42: =D30*$D$14 -> 0 | E42: =E30*$D$14 -> 0 | F42: =F30*$D$14 -> 0 | G42: =G30*$D$14 -> 0 | H42: =H30*$D$14 -> 0 | I42: =I30*$D$14 -> 0 | J42: =J30*$D$14 -> 0 | ... U42: =U30*$D$14 -> 0
A43: DAR | C43: =B40-C40 -> 0 | D43: =C40-D40 -> 0 | E43: =D40-E40 -> 0 | F43: =E40-F40 -> 0 | G43: =F40-G40 -> 0 | H43: =G40-H40 -> 0 | I43: =H40-I40 -> 0 | J43: =I40-J40 -> 0 | ... V43: =U40-V40 -> 0
A44: DAP | C44: =B41-C41 -> 0 | D44: =C41-D41 -> 0 | E44: =D41-E41 -> 0 | F44: =E41-F41 -> 0 | G44: =F41-G41 -> 0 | H44: =G41-H41 -> 0 | I44: =H41-I41 -> 0 | J44: =I41-J41 -> 0 | ... V44: =U41-V41 -> 0
A45: DCB | C45: =C42-B42 -> 0 | D45: =D42-C42 -> 0 | E45: =E42-D42 -> 0 | F45: =F42-E42 -> 0 | G45: =G42-F42 -> 0 | H45: =H42-G42 -> 0 | I45: =I42-H42 -> 0 | J45: =J42-I42 -> 0 | ... V45: =V42-U42 -> 0
...

Sheet TH4_Đất thuê 2
A1: XỬ LÝ ĐẤT ĐAI TRONG THẨM ĐỊNH DỰ ÁN
A2: Trường hợp 4: Đất thuê, thanh toán hàng năm, không điều chỉnh lạm phát
A5: THÔNG SỐ DỰ ÁN (ĐV: TRIỆU ĐỒNG)
A6: Đầu tư | C6: Doanh thu & chi phí hoạt động | F6: Thông tin khác
C7: Chi phí cố định | D7: 1200 | F7: Lạm phát | G7: 0.05
A8: Xây dựng | B8: 30000 | C8: Thuê đất | D8: =10000/20 -> 500 | F8: Thuế TNDN | G8: 0.2
A9: Thiết bị | B9: 20000 | C9: Chi phí biến đổi | D9: 0.2 | E9: /Doanh thu | F9: re thực | G9: 0.1
A10: Tài trợ | C10: Doanh thu/Tỷ lệ tăng | D10: 9000 | E10: 0.03 | F10: re danh nghĩa | G10: =G9+G7+G9*G7 -> 0.155
A11: Vay ngân hàng | B11: =70%*(B8+B9) -> 35000 | C11: Vốn lưu động | F11: WACC | G11: =0.7*B13+0.3*G10 -> 0.11825
A12: Lãi suất thực | B12: 0.05 | C12: AR | D12: 0.1 | E12: /Doanh thu | F12: VAT | G12: 0
A13: Lãi suất danh nghĩa | B13: =B12+G7+B12*G7 -> 0.1025 | C13: AP | D13: 0.1 | E13: /Chi phí biến đổi | F13: Khấu hao | G13: 20
A14: Số năm trả nợ | B14: 10 | C14: CB | D14: 0.05 | E14: /Doanh thu | F14: Vòng đời dự án | G14: 20
A16: CHỈ SỐ GIÁ
A17: Năm | B17: 0 | C17: 1 | D17: 2 | E17: 3 | F17: 4 | G17: 5 | H17: 6 | I17: 7 | J17: 8 | K17: 9 | L17: 10 | M17: 11 | N17: 12 | O17: 13 | P17: 14 | Q17: 15 | R17: 16 | S17: 17 | T17: 18 | U17: 19 | V17: 20
A18: Chỉ số lạm phát | C18: =(1+$G$7)^C17 -> 1.05 | D18: =(1+$G$7)^D17 -> 1.1025 | E18: =(1+$G$7)^E17 -> 1.157625 | F18: =(1+$G$7)^F17 -> 1.2155063 | G18: =(1+$G$7)^G17 -> 1.2762816 | H18: =(1+$G$7)^H17 -> 1.3400956 | I18: =(1+$G$7)^I17 -> 1.4071004 | J18: =(1+$G$7)^J17 -> 1.4774554 | ... V18: =(1+$G$7)^V17 -> 2.6532977
A19: Chỉ số tăng doanh thu | C19: =(1+$E$10)^C17 -> 1.03 | D19: =(1+$E$10)^D17 -> 1.0609 | E19: =(1+$E$10)^E17 -> 1.092727 | F19: =(1+$E$10)^F17 -> 1.1255088 | G19: =(1+$E$10)^G17 -> 1.1592741 | H19: =(1+$E$10)^H17 -> 1.1940523 | I19: =(1+$E$10)^I17 -> 1.2298739 | J19: =(1+$E$10)^J17 -> 1.2667701 | ... V19: =(1+$E$10)^V17 -> 1.8061112
A21: DOANH THU, CHI PHÍ
A22: Năm | B22: 0 | C22: 1 | D22: 2 | E22: 3 | F22: 4 | G22: 5 | H22: 6 | I22: 7 | J22: 8 | K22: 9 | L22: 10 | M22: 11 | N22: 12 | O22: 13 | P22: 14 | Q22: 15 | R22: 16 | S22: 17 | T22: 18 | U22: 19 | V22: 20
A23: Doanh thu
A24: Chi phí cố định | C24: =$D$7 -> 1200 | D24: =$D$7 -> 1200 | E24: =$D$7*$D$18 -> 1323 | F24: =$D$7*$D$18 -> 1323 | G24: =$D$7*$F$18 -> 1458.6075 | H24: =$D$7*$F$18 -> 1458.6075 | I24: =$D$7*$H$18 -> 1608.1148 | J24: =$D$7*$H$18 -> 1608.1148 | K24: =$D$7*$J$18 -> 1772.9465 | L24: =$D$7*$J$18 -> 1772.9465 | M24: =$D$7*$L$18 -> 1954.6736 | N24: =$D$7*$L$18 -> 1954.6736 | O24: =$D$7*$N$18 -> 2155.0276 | P24: =$D$7*$N$18 -> 2155.0276 | Q24: =$D$7*$P$18 -> 2375.9179 | R24: =$D$7*$P$18 -> 2375.9179 | S24: =$D$7*$R$18 -> 2619.4495 | T24: =$D$7*$R$18 -> 2619.4495 | U24: =$D$7*$T$18 -> 2887.9431 | V24: =$D$7*$T$18 -> 2887.9431
A25: Chi phí thuê đất (cố định) | C25: =$D$8 -> 500 | D25: =$D$8 -> 500 | E25: =$D$8 -> 500 | F25: =$D$8 -> 500 | G25: =$D$8 -> 500 | H25: =$D$8 -> 500 | I25: =$D$8 -> 500 | J25: =$D$8 -> 500 | ... V25: =$D$8 -> 500
A26: Chi phí biến đổi | C26: =C23*$D$9 -> 0 | D26: =D23*$D$9 -> 0 | E26: =E23*$D$9 -> 0 | F26: =F23*$D$9 -> 0 | G26: =G23*$D$9 -> 0 | H26: =H23*$D$9 -> 0 | I26: =I23*$D$9 -> 0 | J26: =J23*$D$9 -> 0 | ... V26: =V23*$D$9 -> 0
A28: THUẾ THU NHẬP DOANH NGHIỆP
A29: Năm | B29: 0 | C29: 1 | D29: 2 | E29: 3 | F29: 4 | G29: 5 | H29: 6 | I29: 7 | J29: 8 | K29: 9 | L29: 10 | M29: 11 | N29: 12 | O29: 13 | P29: 14 | Q29: 15 | R29: 16 | S29: 17 | T29: 18 | U29: 19 | V29: 20
A30: Doanh thu | C30: =C23 -> 0 | D30: =D23 -> 0 | E30: =E23 -> 0 | F30: =F23 -> 0 | G30: =G23 -> 0 | H30: =H23 -> 0 | I30: =I23 -> 0 | J30: =J23 -> 0 | ... V30: =V23 -> 0
A31: Chi phí hoạt động | C31: =C24+C26 -> 1200 | D31: =D24+D26 -> 1200 | E31: =E24+E26 -> 1323 | F31: =F24+F26 -> 1323 | G31: =G24+G26 -> 1458.6075 | H31: =H24+H26 -> 1458.6075 | I31: =I24+I26 -> 1608.1148 | J31: =J24+J26 -> 1608.1148 | ... V31: =V24+V26 -> 2887.9431
A32: Chi phí thuê đất (cố định) | C32: =C25 -> 500 | D32: =D25 -> 500 | E32: =E25 -> 500 | F32: =F25 -> 500 | G32: =G25 -> 500 | H32: =H25 -> 500 | I32: =I25 -> 500 | J32: =J25 -> 500 | ... V32: =V25 -> 500
A33: Khấu hao tài sản | C33: =($B$8+$B$9)/$G$13 -> 2500 | D33: =($B$8+$B$9)/$G$13 -> 2500 | E33: =($B$8+$B$9)/$G$13 -> 2500 | F33: =($B$8+$B$9)/$G$13 -> 2500 | G33: =($B$8+$B$9)/$G$13 -> 2500 | H33: =($B$8+$B$9)/$G$13 -> 2500 | I33: =($B$8+$B$9)/$G$13 -> 2500 | J33: =($B$8+$B$9)/$G$13 -> 2500 | ... V33: =($B$8+$B$9)/$G$13 -> 2500
A34: EBIT | C34: =C30-SUM(C31:C33) -> -4200 | D34: =D30-SUM(D31:D33) -> -4200 | E34: =E30-SUM(E31:E33) -> -4323 | F34: =F30-SUM(F31:F33) -> -4323 | G34: =G30-SUM(G31:G33) -> -4458.6075 | H34: =H30-SUM(H31:H33) -> -4458.6075 | I34: =I30-SUM(I31:I33) -> -4608.1148 | J34: =J30-SUM(J31:J33) -> -4608.1148 | ... V34: =V30-SUM(V31:V33) -> -5887.9431
A35: Trả lãi vay
A36: EBT | C36: =C34-C35 -> -4200 | D36: =D34-D35 -> -4200 | E36: =E34-E35 -> -4323 | F36: =F34-F35 -> -4323 | G36: =G34-G35 -> -4458.6075 | H36: =H34-H35 -> -4458.6075 | I36: =I34-I35 -> -4608.1148 | J36: =J34-J35 -> -4608.1148 | ... V36: =V34-V35 -> -5887.9431
A37: Thuế TNDN | C37: =C36*$G$8 -> -840 | D37: =D36*$G$8 -> -840 | E37: =E36*$G$8 -> -864.6 | F37: =F36*$G$8 -> -864.6 | G37: =G36*$G$8 -> -891.7215 | H37: =H36*$G$8 -> -891.7215 | I37: =I36*$G$8 -> -921.62295 | J37: =J36*$G$8 -> -921.62295 | ... V37: =V36*$G$8 -> -1177.5886
A39: VỐN LƯU ĐỘNG
A40: Năm | B40: 0 | C40: 1 | D40: 2 | E40: 3 | F40: 4 | G40: 5 | H40: 6 | I40: 7 | J40: 8 | K40: 9 | L40: 10 | M40: 11 | N40: 12 | O40: 13 | P40: 14 | Q40: 15 | R40: 16 | S40: 17 | T40: 18 | U40: 19 | V40: 20
A41: AR | C41: =C23*$D$12 -> 0 | D41: =D23*$D$12 -> 0 | E41: =E23*$D$12 -> 0 | F41: =F23*$D$12 -> 0 | G41: =G23*$D$12 -> 0 | H41: =H23*$D$12 -> 0 | I41: =I23*$D$12 -> 0 | J41: =J23*$D$12 -> 0 | ... U41: =U23*$D$12 -> 0
A42: AP | C42: =$D$13*C26 -> 0 | D42: =$D$13*D26 -> 0 | E42: =$D$13*E26 -> 0 | F42: =$D$13*F26 -> 0 | G42: =$D$13*G26 -> 0 | H42: =$D$13*H26 -> 0 | I42: =$D$13*I26 -> 0 | J42: =$D$13*J26 -> 0 | ... U42: =$D$13*U26 -> 0
A43: CB | C43: =C30*$D$14 -> 0 | D43: =D30*$D$14 -> 0 | E43: =E30*$D$14 -> 0 | F43: =F30*$D$14 -> 0 | G43: =G30*$D$14 -> 0 | H43: =H30*$D$14 -> 0 | I43: =I30*$D$14 -> 0 | J43: =J30*$D$14 -> 0 | ... U43: =U30*$D$14 -> 0
A44: DAR | C44: =B41-C41 -> 0 | D44: =C41-D41 -> 0 | E44: =D41-E41 -> 0 | F44: =E41-F41 -> 0 | G44: =F41-G41 -> 0 | H44: =G41-H41 -> 0 | I44: =H41-I41 -> 0 | J44: =I41-J41 -> 0 | ... V44: =U41-V41 -> 0
A45: DAP | C45: =B42-C42 -> 0 | D45: =C42-D42 -> 0 | E45: =D42-E42 -> 0 | F45: =E42-F42 -> 0 | G45: =F42-G42 -> 0 | H45: =G42-H42 -> 0 | I45: =H42-I42 -> 0 | J45: =I42-J42 -> 0 | ... V45: =U42-V42 -> 0
A46: DCB | C46: =C43-B43 -> 0 | D46: =D43-C43 -> 0 | E46: =E43-D43 -> 0 | F46: =F43-E43 -> 0 | G46: =G43-F43 -> 0 | H46: =H43-G43 -> 0 | I46: =I43-H43 -> 0 | J46: =J43-I43 -> 0 | ... V46: =V43-U43 -> 0
...

Sheet TH5_Đất thuê 3
A1: XỬ LÝ ĐẤT ĐAI TRONG THẨM ĐỊNH DỰ ÁN
A2: Trường hợp 5: Đất thuê, thanh toán hàng năm theo phương pháp tương đương, không điều chỉnh lạm phát
A5: THÔNG SỐ DỰ ÁN (ĐV: TRIỆU ĐỒNG)
A6: Đầu tư | C6: Doanh thu & chi phí hoạt động | F6: Thông tin khác
C7: Chi phí cố định | D7: 1200 | F7: Lạm phát | G7: 0.05
A8: Xây dựng | B8: 30000 | C8: Thuê đất | D8: =-PMT(B13,20,10000) -> 1194.7023 | F8: Thuế TNDN | G8: 0.2
A9: Thiết bị | B9: 20000 | C9: Chi phí biến đổi | D9: 0.2 | E9: /Doanh thu | F9: re thực | G9: 0.1
A10: Tài trợ | C10: Doanh thu/Tỷ lệ tăng | D10: 9000 | E10: 0.03 | F10: re danh nghĩa | G10: =G9+G7+G9*G7 -> 0.155
A11: Vay ngân hàng | B11: =70%*(B8+B9) -> 35000 | C11: Vốn lưu động | F11: WACC | G11: =0.7*B13+0.3*G10 -> 0.11825
A12: Lãi suất thực | B12: 0.05 | C12: AR | D12: 0.1 | E12: /Doanh thu | F12: VAT | G12: 0
A13: Lãi suất danh nghĩa | B13: =B12+G7+B12*G7 -> 0.1025 | C13: AP | D13: 0.1 | E13: /Chi phí biến đổi | F13: Khấu hao | G13: 20
A14: Số năm trả nợ | B14: 10 | C14: CB | D14: 0.05 | E14: /Doanh thu | F14: Vòng đời dự án | G14: 20
A16: CHỈ SỐ GIÁ
A17: Năm | B17: 0 | C17: 1 | D17: 2 | E17: 3 | F17: 4 | G17: 5 | H17: 6 | I17: 7 | J17: 8 | K17: 9 | L17: 10 | M17: 11 | N17: 12 | O17: 13 | P17: 14 | Q17: 15 | R17: 16 | S17: 17 | T17: 18 | U17: 19 | V17: 20
A18: Chỉ số lạm phát | C18: =(1+$G$7)^C17 -> 1.05 | D18: =(1+$G$7)^D17 -> 1.1025 | E18: =(1+$G$7)^E17 -> 1.157625 | F18: =(1+$G$7)^F17 -> 1.2155063 | G18: =(1+$G$7)^G17 -> 1.2762816 | H18: =(1+$G$7)^H17 -> 1.3400956 | I18: =(1+$G$7)^I17 -> 1.4071004 | J18: =(1+$G$7)^J17 -> 1.4774554 | ... V18: =(1+$G$7)^V17 -> 2.6532977
A19: Chỉ số tăng doanh thu | C19: =(1+$E$10)^C17 -> 1.03 | D19: =(1+$E$10)^D17 -> 1.0609 | E19: =(1+$E$10)^E17 -> 1.092727 | F19: =(1+$E$10)^F17 -> 1.1255088 | G19: =(1+$E$10)^G17 -> 1.1592741 | H19: =(1+$E$10)^H17 -> 1.1940523 | I19: =(1+$E$10)^I17 -> 1.2298739 | J19: =(1+$E$10)^J17 -> 1.2667701 | ... V19: =(1+$E$10)^V17 -> 1.8061112
A21: DOANH THU, CHI PHÍ
A22: Năm | B22: 0 | C22: 1 | D22: 2 | E22: 3 | F22: 4 | G22: 5 | H22: 6 | I22: 7 | J22: 8 | K22: 9 | L22: 10 | M22: 11 | N22: 12 | O22: 13 | P22: 14 | Q22: 15 | R22: 16 | S22: 17 | T22: 18 | U22: 19 | V22: 20
A23: Doanh thu
A24: Chi phí cố định | C24: =$D$7 -> 1200 | D24: =$D$7 -> 1200 | E24: =$D$7*$D$18 -> 1323 | F24: =$D$7*$D$18 -> 1323 | G24: =$D$7*$F$18 -> 1458.6075 | H24: =$D$7*$F$18 -> 1458.6075 | I24: =$D$7*$H$18 -> 1608.1148 | J24: =$D$7*$H$18 -> 1608.1148 | K24: =$D$7*$J$18 -> 1772.9465 | L24: =$D$7*$J$18 -> 1772.9465 | M24: =$D$7*$L$18 -> 1954.6736 | N24: =$D$7*$L$18 -> 1954.6736 | O24: =$D$7*$N$18 -> 2155.0276 | P24: =$D$7*$N$18 -> 2155.0276 | Q24: =$D$7*$P$18 -> 2375.9179 | R24: =$D$7*$P$18 -> 2375.9179 | S24: =$D$7*$R$18 -> 2619.4495 | T24: =$D$7*$R$18 -> 2619.4495 | U24: =$D$7*$T$18 -> 2887.9431 | V24: =$D$7*$T$18 -> 2887.9431
A25: Chi phí thuê đất (cố định) | C25: =$D$8 -> 1194.7023 | D25: =$D$8 -> 1194.7023 | E25: =$D$8 -> 1194.7023 | F25: =$D$8 -> 1194.7023 | G25: =$D$8 -> 1194.7023 | H25: =$D$8 -> 1194.7023 | I25: =$D$8 -> 1194.7023 | J25: =$D$8 -> 1194.7023 | ... V25: =$D$8 -> 1194.7023
A26: Chi phí biến đổi | C26: =C23*$D$9 -> 0 | D26: =D23*$D$9 -> 0 | E26: =E23*$D$9 -> 0 | F26: =F23*$D$9 -> 0 | G26: =G23*$D$9 -> 0 | H26: =H23*$D$9 -> 0 | I26: =I23*$D$9 -> 0 | J26: =J23*$D$9 -> 0 | ... V26: =V23*$D$9 -> 0
A28: THUẾ THU NHẬP DOANH NGHIỆP
A29: Năm | B29: 0 | C29: 1 | D29: 2 | E29: 3 | F29: 4 | G29: 5 | H29: 6 | I29: 7 | J29: 8 | K29: 9 | L29: 10 | M29: 11 | N29: 12 | O29: 13 | P29: 14 | Q29: 15 | R29: 16 | S29: 17 | T29: 18 | U29: 19 | V29: 20
A30: Doanh thu | C30: =C23 -> 0 | D30: =D23 -> 0 | E30: =E23 -> 0 | F30: =F23 -> 0 | G30: =G23 -> 0 | H30: =H23 -> 0 | I30: =I23 -> 0 | J30: =J23 -> 0 | ... V30: =V23 -> 0
A31: Chi phí hoạt động | C31: =SUM(C24:C26) -> 2394.7023 | D31: =SUM(D24:D26) -> 2394.7023 | E31: =SUM(E24:E26) -> 2517.7023 | F31: =SUM(F24:F26) -> 2517.7023 | G31: =SUM(G24:G26) -> 2653.3098 | H31: =SUM(H24:H26) -> 2653.3098 | I31: =SUM(I24:I26) -> 2802.8171 | J31: =SUM(J24:J26) -> 2802.8171 | ... V31: =SUM(V24:V26) -> 4082.6454
A32: Khấu hao tài sản | C32: =($B$8+$B$9)/$G$13 -> 2500 | D32: =($B$8+$B$9)/$G$13 -> 2500 | E32: =($B$8+$B$9)/$G$13 -> 2500 | F32: =($B$8+$B$9)/$G$13 -> 2500 | G32: =($B$8+$B$9)/$G$13 -> 2500 | H32: =($B$8+$B$9)/$G$13 -> 2500 | I32: =($B$8+$B$9)/$G$13 -> 2500 | J32: =($B$8+$B$9)/$G$13 -> 2500 | ... V32: =($B$8+$B$9)/$G$13 -> 2500
A33: EBIT | C33: =C30-SUM(C31:C32) -> -4894.7023 | D33: =D30-SUM(D31:D32) -> -4894.7023 | E33: =E30-SUM(E31:E32) -> -5017.7023 | F33: =F30-SUM(F31:F32) -> -5017.7023 | G33: =G30-SUM(G31:G32) -> -5153.3098 | H33: =H30-SUM(H31:H32) -> -5153.3098 | I33: =I30-SUM(I31:I32) -> -5302.8171 | J33: =J30-SUM(J31:J32) -> -5302.8171 | ... V33: =V30-SUM(V31:V32) -> -6582.6454
A34: Trả lãi vay
A35: EBT | C35: =C33-C34 -> -4894.7023 | D35: =D33-D34 -> -4894.7023 | E35: =E33-E34 -> -5017.7023 | F35: =F33-F34 -> -5017.7023 | G35: =G33-G34 -> -5153.3098 | H35: =H33-H34 -> -5153.3098 | I35: =I33-I34 -> -5302.8171 | J35: =J33-J34 -> -5302.8171 | ... V35: =V33-V34 -> -6582.6454
A36: Thuế TNDN | C36: =C35*$G$8 -> -978.94046 | D36: =D35*$G$8 -> -978.94046 | E36: =E35*$G$8 -> -1003.5405 | F36: =F35*$G$8 -> -1003.5405 | G36: =G35*$G$8 -> -1030.662 | H36: =H35*$G$8 -> -1030.662 | I36: =I35*$G$8 -> -1060.5634 | J36: =J35*$G$8 -> -1060.5634 | ... V36: =V35*$G$8 -> -1316.5291
A38: VỐN LƯU ĐỘNG
A39: Năm | B39: 0 | C39: 1 | D39: 2 | E39: 3 | F39: 4 | G39: 5 | H39: 6 | I39: 7 | J39: 8 | K39: 9 | L39: 10 | M39: 11 | N39: 12 | O39: 13 | P39: 14 | Q39: 15 | R39: 16 | S39: 17 | T39: 18 | U39: 19 | V39: 20
A40: AR | C40: =C23*$D$12 -> 0 | D40: =D23*$D$12 -> 0 | E40: =E23*$D$12 -> 0 | F40: =F23*$D$12 -> 0 | G40: =G23*$D$12 -> 0 | H40: =H23*$D$12 -> 0 | I40: =I23*$D$12 -> 0 | J40: =J23*$D$12 -> 0 | ... U40: =U23*$D$12 -> 0
A41: AP | C41: =$D$13*C26 -> 0 | D41: =$D$13*D26 -> 0 | E41: =$D$13*E26 -> 0 | F41: =$D$13*F26 -> 0 | G41: =$D$13*G26 -> 0 | H41: =$D$13*H26 -> 0 | I41: =$D$13*I26 -> 0 | J41: =$D$13*J26 -> 0 | ... U41: =$D$13*U26 -> 0
A42: CB | C42: =C30*$D$14 -> 0 | D42: =D30*$D$14 -> 0 | E42: =E30*$D$14 -> 0 | F42: =F30*$D$14 -> 0 | G42: =G30*$D$14 -> 0 | H42: =H30*$D$14 -> 0 | I42: =I30*$D$14 -> 0 | J42: =J30*$D$14 -> 0 | ... U42: =U30*$D$14 -> 0
A43: DAR | C43: =B40-C40 -> 0 | D43: =C40-D40 -> 0 | E43: =D40-E40 -> 0 | F43: =E40-F40 -> 0 | G43: =F40-G40 -> 0 | H43: =G40-H40 -> 0 | I43: =H40-I40 -> 0 | J43: =I40-J40 -> 0 | ... V43: =U40-V40 -> 0
A44: DAP | C44: =B41-C41 -> 0 | D44: =C41-D41 -> 0 | E44: =D41-E41 -> 0 | F44: =E41-F41 -> 0 | G44: =F41-G41 -> 0 | H44: =G41-H41 -> 0 | I44: =H41-I41 -> 0 | J44: =I41-J41 -> 0 | ... V44: =U41-V41 -> 0
A45: DCB | C45: =C42-B42 -> 0 | D45: =D42-C42 -> 0 | E45: =E42-D42 -> 0 | F45: =F42-E42 -> 0 | G45: =G42-F42 -> 0 | H45: =H42-G42 -> 0 | I45: =I42-H42 -> 0 | J45: =J42-I42 -> 0 | ... V45: =V42-U42 -> 0
A47: BÁO CÁO NGÂN LƯU TIPV
...

Sheet TH6_Đất thuê 4
A1: XỬ LÝ ĐẤT ĐAI TRONG THẨM ĐỊNH DỰ ÁN
A2: Trường hợp 6: Đất thuê, thanh toán hàng năm, điều chỉnh lạm phát (2 năm/lần)
A5: THÔNG SỐ DỰ ÁN (ĐV: TRIỆU ĐỒNG)
A6: Đầu tư | C6: Doanh thu & chi phí hoạt động | F6: Thông tin khác
C7: Chi phí cố định | D7: 1200 | F7: Lạm phát | G7: 0.05
A8: Xây dựng | B8: 30000 | C8: Thuê đất | D8: =10000/20 -> 500 | F8: Thuế TNDN | G8: 0.2
A9: Thiết bị | B9: 20000 | C9: Chi phí biến đổi | D9: 0.2 | E9: /Doanh thu | F9: re thực | G9: 0.1
A10: Tài trợ | C10: Doanh thu/Tỷ lệ tăng | D10: 9000 | E10: 0.03 | F10: re danh nghĩa | G10: =G9+G7+G9*G7 -> 0.155
A11: Vay ngân hàng | B11: =70%*(B8+B9) -> 35000 | C11: Vốn lưu động | F11: WACC | G11: =0.7*B13+0.3*G10 -> 0.11825
A12: Lãi suất thực | B12: 0.05 | C12: AR | D12: 0.1 | E12: /Doanh thu | F12: VAT | G12: 0
A13: Lãi suất danh nghĩa | B13: =B12+G7+B12*G7 -> 0.1025 | C13: AP | D13: 0.1 | E13: /Chi phí biến đổi | F13: Khấu hao | G13: 20
A14: Số năm trả nợ | B14: 10 | C14: CB | D14: 0.05 | E14: /Doanh thu | F14: Vòng đời dự án | G14: 20
A16: CHỈ SỐ GIÁ
A17: Năm | B17: 0 | C17: 1 | D17: 2 | E17: 3 | F17: 4 | G17: 5 | H17: 6 | I17: 7 | J17: 8 | K17: 9 | L17: 10 | M17: 11 | N17: 12 | O17: 13 | P17: 14 | Q17: 15 | R17: 16 | S17: 17 | T17: 18 | U17: 19 | V17: 20
A18: Chỉ số lạm phát | C18: =(1+$G$7)^C17 -> 1.05 | D18: =(1+$G$7)^D17 -> 1.1025 | E18: =(1+$G$7)^E17 -> 1.157625 | F18: =(1+$G$7)^F17 -> 1.2155063 | G18: =(1+$G$7)^G17 -> 1.2762816 | H18: =(1+$G$7)^H17 -> 1.3400956 | I18: =(1+$G$7)^I17 -> 1.4071004 | J18: =(1+$G$7)^J17 -> 1.4774554 | ... V18: =(1+$G$7)^V17 -> 2.6532977
A19: Chỉ số tăng doanh thu | C19: =(1+$E$10)^C17 -> 1.03 | D19: =(1+$E$10)^D17 -> 1.0609 | E19: =(1+$E$10)^E17 -> 1.092727 | F19: =(1+$E$10)^F17 -> 1.1255088 | G19: =(1+$E$10)^G17 -> 1.1592741 | H19: =(1+$E$10)^H17 -> 1.1940523 | I19: =(1+$E$10)^I17 -> 1.2298739 | J19: =(1+$E$10)^J17 -> 1.2667701 | ... V19: =(1+$E$10)^V17 -> 1.8061112
A21: DOANH THU, CHI PHÍ
A22: Năm | B22: 0 | C22: 1 | D22: 2 | E22: 3 | F22: 4 | G22: 5 | H22: 6 | I22: 7 | J22: 8 | K22: 9 | L22: 10 | M22: 11 | N22: 12 | O22: 13 | P22: 14 | Q22: 15 | R22: 16 | S22: 17 | T22: 18 | U22: 19 | V22: 20
A23: Doanh thu
A24: Chi phí cố định | C24: =$D$7 -> 1200 | D24: =$D$7 -> 1200 | E24: =$D$7*$D$18 -> 1323 | F24: =$D$7*$D$18 -> 1323 | G24: =$D$7*$F$18 -> 1458.6075 | H24: =$D$7*$F$18 -> 1458.6075 | I24: =$D$7*$H$18 -> 1608.1148 | J24: =$D$7*$H$18 -> 1608.1148 | K24: =$D$7*$J$18 -> 1772.9465 | L24: =$D$7*$J$18 -> 1772.9465 | M24: =$D$7*$L$18 -> 1954.6736 | N24: =$D$7*$L$18 -> 1954.6736 | O24: =$D$7*$N$18 -> 2155.0276 | P24: =$D$7*$N$18 -> 2155.0276 | Q24: =$D$7*$P$18 -> 2375.9179 | R24: =$D$7*$P$18 -> 2375.9179 | S24: =$D$7*$R$18 -> 2619.4495 | T24: =$D$7*$R$18 -> 2619.4495 | U24: =$D$7*$T$18 -> 2887.9431 | V24: =$D$7*$T$18 -> 2887.9431
A25: Chi phí thuê đất (cố định) | C25: =$D$8 -> 500 | D25: =$D$8 -> 500 | E25: =$D$8*$D$18 -> 551.25 | F25: =$D$8*$D$18 -> 551.25 | G25: =$D$8*$F$18 -> 607.75312 | H25: =$D$8*$F$18 -> 607.75312 | I25: =$D$8*$H$18 -> 670.04782 | J25: =$D$8*$H$18 -> 670.04782 | K25: =$D$8*$J$18 -> 738.72772 | L25: =$D$8*$J$18 -> 738.72772 | M25: =$D$8*$L$18 -> 814.44731 | N25: =$D$8*$L$18 -> 814.44731 | O25: =$D$8*$N$18 -> 897.92816 | P25: =$D$8*$N$18 -> 897.92816 | Q25: =$D$8*$P$18 -> 989.9658 | R25: =$D$8*$P$18 -> 989.9658 | S25: =$D$8*$R$18 -> 1091.4373 | T25: =$D$8*$R$18 -> 1091.4373 | U25: =$D$8*$T$18 -> 1203.3096 | V25: =$D$8*$T$18 -> 1203.3096
A26: Chi phí biến đổi | C26: =C23*$D$9 -> 0 | D26: =D23*$D$9 -> 0 | E26: =E23*$D$9 -> 0 | F26: =F23*$D$9 -> 0 | G26: =G23*$D$9 -> 0 | H26: =H23*$D$9 -> 0 | I26: =I23*$D$9 -> 0 | J26: =J23*$D$9 -> 0 | ... V26: =V23*$D$9 -> 0
A28: THUẾ THU NHẬP DOANH NGHIỆP
A29: Năm | B29: 0 | C29: 1 | D29: 2 | E29: 3 | F29: 4 | G29: 5 | H29: 6 | I29: 7 | J29: 8 | K29: 9 | L29: 10 | M29: 11 | N29: 12 | O29: 13 | P29: 14 | Q29: 15 | R29: 16 | S29: 17 | T29: 18 | U29: 19 | V29: 20
A30: Doanh thu | C30: =C23 -> 0 | D30: =D23 -> 0 | E30: =E23 -> 0 | F30: =F23 -> 0 | G30: =G23 -> 0 | H30: =H23 -> 0 | I30: =I23 -> 0 | J30: =J23 -> 0 | ... V30: =V23 -> 0
A31: Chi phí hoạt động | C31: =SUM(C24:C26) -> 1700 | D31: =SUM(D24:D26) -> 1700 | E31: =SUM(E24:E26) -> 1874.25 | F31: =SUM(F24:F26) -> 1874.25 | G31: =SUM(G24:G26) -> 2066.3606 | H31: =SUM(H24:H26) -> 2066.3606 | I31: =SUM(I24:I26) -> 2278.1626 | J31: =SUM(J24:J26) -> 2278.1626 | ... V31: =SUM(V24:V26) -> 4091.2527
A32: Khấu hao tài sản | C32: =($B$8+$B$9)/$G$13 -> 2500 | D32: =($B$8+$B$9)/$G$13 -> 2500 | E32: =($B$8+$B$9)/$G$13 -> 2500 | F32: =($B$8+$B$9)/$G$13 -> 2500 | G32: =($B$8+$B$9)/$G$13 -> 2500 | H32: =($B$8+$B$9)/$G$13 -> 2500 | I32: =($B$8+$B$9)/$G$13 -> 2500 | J32: =($B$8+$B$9)/$G$13 -> 2500 | ... V32: =($B$8+$B$9)/$G$13 -> 2500
A33: EBIT | C33: =C30-SUM(C31:C32) -> -4200 | D33: =D30-SUM(D31:D32) -> -4200 | E33: =E30-SUM(E31:E32) -> -4374.25 | F33: =F30-SUM(F31:F32) -> -4374.25 | G33: =G30-SUM(G31:G32) -> -4566.3606 | H33: =H30-SUM(H31:H32) -> -4566.3606 | I33: =I30-SUM(I31:I32) -> -4778.1626 | J33: =J30-SUM(J31:J32) -> -4778.1626 | ... V33: =V30-SUM(V31:V32) -> -6591.2527
A34: Trả lãi vay
A35: EBT | C35: =C33-C34 -> -4200 | D35: =D33-D34 -> -4200 | E35: =E33-E34 -> -4374.25 | F35: =F33-F34 -> -4374.25 | G35: =G33-G34 -> -4566.3606 | H35: =H33-H34 -> -4566.3606 | I35: =I33-I34 -> -4778.1626 | J35: =J33-J34 -> -4778.1626 | ... V35: =V33-V34 -> -6591.2527
A36: Thuế TNDN | C36: =C35*$G$8 -> -840 | D36: =D35*$G$8 -> -840 | E36: =E35*$G$8 -> -874.85 | F36: =F35*$G$8 -> -874.85 | G36: =G35*$G$8 -> -913.27213 | H36: =H35*$G$8 -> -913.27213 | I36: =I35*$G$8 -> -955.63252 | J36: =J35*$G$8 -> -955.63252 | ... V36: =V35*$G$8 -> -1318.2505
A38: VỐN LƯU ĐỘNG
A39: Năm | B39: 0 | C39: 1 | D39: 2 | E39: 3 | F39: 4 | G39: 5 | H39: 6 | I39: 7 | J39: 8 | K39: 9 | L39: 10 | M39: 11 | N39: 12 | O39: 13 | P39: 14 | Q39: 15 | R39: 16 | S39: 17 | T39: 18 | U39: 19 | V39: 20
A40: AR | C40: =C23*$D$12 -> 0 | D40: =D23*$D$12 -> 0 | E40: =E23*$D$12 -> 0 | F40: =F23*$D$12 -> 0 | G40: =G23*$D$12 -> 0 | H40: =H23*$D$12 -> 0 | I40: =I23*$D$12 -> 0 | J40: =J23*$D$12 -> 0 | ... U40: =U23*$D$12 -> 0
A41: AP | C41: =$D$13*C26 -> 0 | D41: =$D$13*D26 -> 0 | E41: =$D$13*E26 -> 0 | F41: =$D$13*F26 -> 0 | G41: =$D$13*G26 -> 0 | H41: =$D$13*H26 -> 0 | I41: =$D$13*I26 -> 0 | J41: =$D$13*J26 -> 0 | ... U41: =$D$13*U26 -> 0
A42: CB | C42: =C30*$D$14 -> 0 | D42: =D30*$D$14 -> 0 | E42: =E30*$D$14 -> 0 | F42: =F30*$D$14 -> 0 | G42: =G30*$D$14 -> 0 | H42: =H30*$D$14 -> 0 | I42: =I30*$D$14 -> 0 | J42: =J30*$D$14 -> 0 | ... U42: =U30*$D$14 -> 0
A43: DAR | C43: =B40-C40 -> 0 | D43: =C40-D40 -> 0 | E43: =D40-E40 -> 0 | F43: =E40-F40 -> 0 | G43: =F40-G40 -> 0 | H43: =G40-H40 -> 0 | I43: =H40-I40 -> 0 | J43: =I40-J40 -> 0 | ... V43: =U40-V40 -> 0
A44: DAP | C44: =B41-C41 -> 0 | D44: =C41-D41 -> 0 | E44: =D41-E41 -> 0 | F44: =E41-F41 -> 0 | G44: =F41-G41 -> 0 | H44: =G41-H41 -> 0 | I44: =H41-I41 -> 0 | J44: =I41-J41 -> 0 | ... V44: =U41-V41 -> 0
A45: DCB | C45: =C42-B42 -> 0 | D45: =D42-C42 -> 0 | E45: =E42-D42 -> 0 | F45: =F42-E42 -> 0 | G45: =G42-F42 -> 0 | H45: =H42-G42 -> 0 | I45: =I42-H42 -> 0 | J45: =J42-I42 -> 0 | ... V45: =V42-U42 -> 0
A47: BÁO CÁO NGÂN LƯU TIPV
...
