Workbook

Sheet Trả lời của sinh viên
B2: HỌC PHẦN: THỰC HÀNH THẨM ĐỊNH DỰ ÁN HỌ VÀ TÊN: NGÀNH: KINH TẾ ĐẦU TƯ - K45 (KHOA KINH TẾ, UEH) | E2: Yêu cầu: Hãy hoàn thành các ô bị bỏ trống (được tô màu VÀNG) ở hai bảng tính của Phương án 1 và Phương án 2 bằng cách sử dụng công thức thích hợp liên kết với bảng Thông số đã cho sẵn. Có thể thực hiện phân tích độ nhạy với các thông số như lạm phát, tỷ lệ người sử dụng chuyển sang sử dụng đường cao tốc, ... cho việc phân tích của bạn. Ngoài ra, bạn cũng có thể "Copy or Move" một phương án để tạo thêm một phương án mới (ví dụ: Cho EPV thu phí kéo dài thêm 5 năm, ...). Cho biết nên chọn phương án nào? Tại sao? (Lưu ý: Không được Insert/Delete bất cứ dòng hoặc cột nào trong các bảng tính cho sẵn; Có thể sử dụng đồ thị, lập bảng so sánh, ... để hỗ trợ việc phân tích của bạn. Phần trả lời của bạn PHẢI được thực hiện ở bảng tính này).

Sheet Thông số
B2: CASE 9: HIGHWAY PROJECT
B4: HAI PHƯƠNG ÁN
B5: PHƯƠNG ÁN 1: CHỦ ĐẦU TƯ BÀN GIAO DỰ ÁN CHO GOJ KHÔNG TỐN PHÍ, VÀ GOJ TIẾP TỤC THU PHÍ SAU NĂM 2033 => TRẠM THU PHÍ CHƯA THANH LÝ VÀO NĂM 2033, VÀ SẼ THANH LÝ VÀO NĂM 2058 (NĂM 45).
B6: PHƯƠNG ÁN 2: CHỦ ĐẦU TƯ BÀN GIAO DỰ ÁN CHO GOJ KHÔNG TỐN PHÍ, VÀ GOJ SẼ KHÔNG THU PHÍ SAU NĂM 2033 => TRẠM THU PHÍ ĐƯỢC THANH LÝ VÀO NĂM 2033 (NĂM 20); CÓ NHIỀU LỢI ÍCH TĂNG THÊM (NHƯNG KHÔNG CÒN DOANH THU TỪ TRẠM THU PHÍ).
B8: THÔNG TIN CHUNG | D8: CƠ CẤU VỐN | E8: Chi phí vốn (thực) | F8: Triệu US$ | G8: Triệu J$ | H8: Tỷ trọng | I8: Chi phí vốn (danh nghĩa)
B9: Tỷ giá hối đoái J$/US$ | C9: 80 | D9: Vay nước ngoài (Triệu US$) | E9: 0.03 | F9: 200 | G9: =F9*F24 -> 18992.876 | H9: =G9/G12 -> 0.21892995 | I9: =E9+$C$11+E9*$C$11 -> 0.0506
B10: Tỷ lệ lạm phát, J$ (%/năm) | C10: 0.08 | D10: Vay trong nước (Triệu US$) | E10: 0.045 | F10: 600 | G10: =F10*F24 -> 56978.628 | H10: =G10/G12 -> 0.65678985 | I10: =E10+$C$11+E10*$C$11 -> 0.0659
B11: Tỷ lệ lạm phát, US$ (%/năm) | C11: 0.02 | D11: Chủ đầu tư | E11: 0.12 | G11: =G12-G9-G10 -> 10781.707 | H11: =G11/G12 -> 0.1242802 | I11: =E11+$C$11+E11*$C$11 -> 0.1424
B12: Thuế bán hàng/VAT (%, nhập lượng trong nước) | C12: 0.1 | D12: Tổng | G12: =I42+I70 -> 86753.211 | H12: WACC | I12: =SUMPRODUCT(H9:H11,I9:I11) -> 0.072057807
B13: Thuế nhập khẩu (%/CIF) | C13: 0.05
D14: Mức tăng lưu lượng xe lưu thông trên các tuyến đường/năm | F14: 0.04 | G14: (từ năm 2018)
B15: Tuyến đường (Xem Hình minh họa) | C15: Tổng dự báo (xe/ngày) | D15: Trong đó: | E15: Tỷ lệ | F15: 2017-2018 | G15: 2019 trở đi | H15: Giá ẩn lao động không kỹ năng | I15: 0.2
B16: Queens Town - Williamsburg | C16: 10000 | D16: Lưu lượng xe sử dụng cao tốc | E16: 0.6 | F16: 0.36 | G16: 1 | H16: Giá ẩn của đất | I16: 0.5
B17: Williamsburg - Hope Bay | C17: 4000 | D17: Xe khách | E17: 0.6
B18: Williamsburg - Black Town | C18: 2000 | D18: Xe tải | E18: =1-E17 -> 0.4 | F18: Thuế thu nhập doanh nghiệp | G18: 0.25 | H18: Hệ số chuyển đổi | I18: 1000000
B20: Năm dự án | C20: 0 | D20: 1 | E20: 2 | F20: 3 | G20: 4 | H20: 5 | I20: 6
B21: 1) CHỈ SỐ GIÁ | C21: 2013 | D21: 2014 | E21: 2015 | F21: 2016 | G21: 2017 | H21: 2018 | I21: 2019
B22: Chỉ số lạm phát, J$ | C22: =(1+$C$10)^C20 -> 1 | D22: =(1+$C$10)^D20 -> 1.08 | E22: =(1+$C$10)^E20 -> 1.1664 | F22: =(1+$C$10)^F20 -> 1.259712 | G22: =(1+$C$10)^G20 -> 1.360489 | H22: =(1+$C$10)^H20 -> 1.4693281 | I22: =(1+$C$10)^I20 -> 1.5868743
B23: Chỉ số lạm phát, US$ | C23: =(1+$C$11)^C20 -> 1 | D23: =(1+$C$11)^D20 -> 1.02 | E23: =(1+$C$11)^E20 -> 1.0404 | F23: =(1+$C$11)^F20 -> 1.061208 | G23: =(1+$C$11)^G20 -> 1.0824322 | H23: =(1+$C$11)^H20 -> 1.1040808 | I23: =(1+$C$11)^I20 -> 1.1261624
B24: Tỷ giá hối đối danh nghĩa (J$/US$) | C24: =$C$9*C22/C23 -> 80 | D24: =$C$9*D22/D23 -> 84.705882 | E24: =$C$9*E22/E23 -> 89.688581 | F24: =$C$9*F22/F23 -> 94.96438 | G24: =$C$9*G22/G23 -> 100.55052 | H24: =$C$9*H22/H23 -> 106.46526 | I24: =$C$9*I22/I23 -> 112.72792
B26: 2) CHI PHÍ ĐẦU TƯ (GIÁ NĂM 2013) | C26: 2013 | D26: 2014 | E26: 2015 | F26: 2016 | G26: 2017 | H26: 2018 | I26: Tổng chi phí (Triệu J$)
B27: XÂY DỰNG ĐƯỜNG CAO TỐC/NĂM (TÀI CHÍNH, TRIỆU J$)
B28: Lao động
B29: Trong nước | C29: 640 | D29: 960 | E29: 960 | F29: 2000 | G29: 4000 | H29: 4800 | I29: =SUM(C29:H29) -> 13360
B30: Nước ngoài | C30: 640 | D30: 1120 | E30: 1120 | F30: 800 | G30: 2000 | H30: 800 | I30: =SUM(C30:H30) -> 6480
B31: Nguyên vật liệu
B32: Trong nước | C32: =C51*(1+$C$12) -> 480 | D32: =D51*(1+$C$12) -> 800 | E32: =E51*(1+$C$12) -> 800 | F32: =F51*(1+$C$12) -> 800 | G32: =G51*(1+$C$12) -> 800 | H32: =H51*(1+$C$12) -> 2400 | I32: =SUM(C32:H32) -> 6080
B33: Nhập khẩu | C33: =C52*(1+$C$13) -> 960 | D33: =D52*(1+$C$13) -> 2240 | E33: =E52*(1+$C$13) -> 2240 | F33: =F52*(1+$C$13) -> 3200 | G33: =G52*(1+$C$13) -> 4800 | H33: =H52*(1+$C$13) -> 2400 | I33: =SUM(C33:H33) -> 15840
B34: Thiết bị
B35: Trong nước | C35: =C54*(1+$C$12) -> 320 | D35: =D54*(1+$C$12) -> 640 | E35: =E54*(1+$C$12) -> 640 | F35: =F54*(1+$C$12) -> 1200 | G35: =G54*(1+$C$12) -> 1600 | H35: =H54*(1+$C$12) -> 800 | I35: =SUM(C35:H35) -> 5200
B36: Nhập khẩu | C36: =C55*(1+$C$13) -> 1760 | D36: =D55*(1+$C$13) -> 2240 | E36: =E55*(1+$C$13) -> 2240 | F36: =F55*(1+$C$13) -> 1600 | G36: =G55*(1+$C$13) -> 2800 | H36: =H55*(1+$C$13) -> 800 | I36: =SUM(C36:H36) -> 11440
B37: Đất | C37: 3200 | F37: 6400 | I37: =SUM(C37:H37) -> 9600
B38: Tổng chi phí (thực, bao gồm các loại thuế, chưa tính đất) | C38: =SUM(C29:C36) -> 4800 | D38: =SUM(D29:D36) -> 8000 | E38: =SUM(E29:E36) -> 8000 | F38: =SUM(F29:F36) -> 9600 | G38: =SUM(G29:G36) -> 16000 | H38: =SUM(H29:H36) -> 12000 | I38: =SUM(I29:I36) -> 58400
B39: Tổng chi phí (thực, bao gồm các loại thuế, có tính đất) | C39: =SUM(C29:C37) -> 8000 | D39: =SUM(D29:D37) -> 8000 | E39: =SUM(E29:E37) -> 8000 | F39: =SUM(F29:F37) -> 16000 | G39: =SUM(G29:G37) -> 16000 | H39: =SUM(H29:H37) -> 12000 | I39: =SUM(I29:I37) -> 68000
B40: Vốn chủ đầu tư | C40: 4000 | D40: 4000 | E40: 4000 | F40: 8000 | G40: 8000 | I40: =SUM(C40:H40) -> 28000
B41: Vốn GOJ | C41: 4000 | D41: 4000 | E41: 4000 | F41: 8000 | G41: 8000 | H41: 12000 | I41: =SUM(C41:H41) -> 40000
B42: Tổng chi phí (danh nghĩa, bao gồm các loại thuế, có tính đất) | C42: =C39*C22 -> 8000 | D42: =D39*D22 -> 8640 | E42: =E39*E22 -> 9331.2 | F42: =F39*F22 -> 20155.392 | G42: =G39*G22 -> 21767.823 | H42: =H39*H22 -> 17631.937 | I42: =SUM(C42:H42) -> 85526.352
B43: Thuế VAT (thực) | C43: =(C32-C51)+(C35-C54) -> 72.727273 | D43: =(D32-D51)+(D35-D54) -> 130.90909 | E43: =(E32-E51)+(E35-E54) -> 130.90909 | F43: =(F32-F51)+(F35-F54) -> 181.81818 | G43: =(G32-G51)+(G35-G54) -> 218.18182 | H43: =(H32-H51)+(H35-H54) -> 290.90909
B44: Tổng chi phí tài chính (thực, trừ VAT, chưa tính đất) | C44: =C38-C43 -> 4727.2727 | D44: =D38-D43 -> 7869.0909 | E44: =E38-E43 -> 7869.0909 | F44: =F38-F43 -> 9418.1818 | G44: =G38-G43 -> 15781.818 | H44: =H38-H43 -> 11709.091 | I44: =SUM(C44:H44) -> 57374.545
B45: Tổng chi phí tài chính (hiện hành, trừ VAT, chưa tính đất) | C45: =C44*C22 -> 4727.2727 | D45: =D44*D22 -> 8498.6182 | E45: =E44*E22 -> 9178.5076 | F45: =F44*F22 -> 11864.197 | G45: =G44*G22 -> 21470.989 | H45: =H44*H22 -> 17204.496 | I45: =SUM(C45:H45) -> 72944.081
...

Sheet Phương án 1_Thu phí
B2: PHƯƠNG ÁN 1: CHÍNH PHỦ SẼ THU PHÍ SAU NĂM 2033
B4: CHỈ SỐ GIÁ
B5: Năm | C5: 2013 | D5: 2014 | E5: 2015 | F5: 2016 | G5: 2017 | H5: 2018 | I5: 2019 | J5: 2020 | K5: 2021 | L5: 2022 | M5: 2023 | N5: 2024 | O5: 2025 | P5: 2026 | Q5: 2027 | R5: 2028 | S5: 2029 | T5: 2030 | U5: 2031 | V5: 2032 | W5: 2033 | X5: 2034 | Y5: 2035 | Z5: 2036 | AA5: 2037 | AB5: 2038 | AC5: 2039 | AD5: 2040 | AE5: 2041 | AF5: 2042 | AG5: 2043 | AH5: 2044 | AI5: 2045 | AJ5: 2046 | AK5: 2047 | AL5: 2048 | AM5: 2049 | AN5: 2050 | AO5: 2051 | AP5: 2052 | AQ5: 2053 | AR5: 2054 | AS5: 2055 | AT5: 2056 | AU5: 2057 | AV5: 2058
B6: Năm dự án | C6: 0 | D6: 1 | E6: 2 | F6: 3 | G6: 4 | H6: 5 | I6: 6 | J6: 7 | K6: 8 | L6: 9 | M6: 10 | N6: 11 | O6: 12 | P6: 13 | Q6: 14 | R6: 15 | S6: 16 | T6: 17 | U6: 18 | V6: 19 | W6: 20 | X6: 21 | Y6: 22 | Z6: 23 | AA6: 24 | AB6: 25 | AC6: 26 | AD6: 27 | AE6: 28 | AF6: 29 | AG6: 30 | AH6: 31 | AI6: 32 | AJ6: 33 | AK6: 34 | AL6: 35 | AM6: 36 | AN6: 37 | AO6: 38 | AP6: 39 | AQ6: 40 | AR6: 41 | AS6: 42 | AT6: 43 | AU6: 44 | AV6: 45
B7: Chỉ số lạm phát trong nước | C7: =(1+'Thông số'!$C$10)^C6 -> 1 | D7: =(1+'Thông số'!$C$10)^D6 -> 1.08 | E7: =(1+'Thông số'!$C$10)^E6 -> 1.1664 | F7: =(1+'Thông số'!$C$10)^F6 -> 1.259712 | G7: =(1+'Thông số'!$C$10)^G6 -> 1.360489 | H7: =(1+'Thông số'!$C$10)^H6 -> 1.4693281 | I7: =(1+'Thông số'!$C$10)^I6 -> 1.5868743 | J7: =(1+'Thông số'!$C$10)^J6 -> 1.7138243 | ... AV7: =(1+'Thông số'!$C$10)^AV6 -> 31.920449
B8: Chỉ số lạm phát nước ngoài | C8: =(1+'Thông số'!$C$11)^C6 -> 1 | D8: =(1+'Thông số'!$C$11)^D6 -> 1.02 | E8: =(1+'Thông số'!$C$11)^E6 -> 1.0404 | F8: =(1+'Thông số'!$C$11)^F6 -> 1.061208 | G8: =(1+'Thông số'!$C$11)^G6 -> 1.0824322 | H8: =(1+'Thông số'!$C$11)^H6 -> 1.1040808 | I8: =(1+'Thông số'!$C$11)^I6 -> 1.1261624 | J8: =(1+'Thông số'!$C$11)^J6 -> 1.1486857 | ... AV8: =(1+'Thông số'!$C$11)^AV6 -> 2.4378542
B9: Tỷ giá hối đối danh nghĩa | C9: ='Thông số'!$C$9*C7/C8 -> 80 | D9: ='Thông số'!$C$9*D7/D8 -> 84.705882 | E9: ='Thông số'!$C$9*E7/E8 -> 89.688581 | F9: ='Thông số'!$C$9*F7/F8 -> 94.96438 | G9: ='Thông số'!$C$9*G7/G8 -> 100.55052 | H9: ='Thông số'!$C$9*H7/H8 -> 106.46526 | I9: ='Thông số'!$C$9*I7/I8 -> 112.72792 | J9: ='Thông số'!$C$9*J7/J8 -> 119.35897 | ... AV9: ='Thông số'!$C$9*AV7/AV8 -> 1047.4933
B10: Chỉ số tăng lưu lượng xe | G10: =(1+'Thông số'!$F$14)^C6 -> 1 | H10: =(1+'Thông số'!$F$14)^D6 -> 1.04 | I10: =(1+'Thông số'!$F$14)^E6 -> 1.0816 | J10: =(1+'Thông số'!$F$14)^F6 -> 1.124864 | K10: =(1+'Thông số'!$F$14)^G6 -> 1.1698586 | L10: =(1+'Thông số'!$F$14)^H6 -> 1.2166529 | M10: =(1+'Thông số'!$F$14)^I6 -> 1.265319 | N10: =(1+'Thông số'!$F$14)^J6 -> 1.3159318 | ... AV10: =(1+'Thông số'!$F$14)^AR6 -> 4.9930615
B12: LỊCH VAY VÀ TRẢ NỢ (TRIỆU US$)
B13: =B6 -> Năm dự án | C13: =C6 -> 0 | D13: =D6 -> 1 | E13: =E6 -> 2 | F13: =F6 -> 3 | G13: =G6 -> 4 | H13: =H6 -> 5 | I13: =I6 -> 6 | ... AV13: =AV6 -> 45
B14: Vay ngân hàng nước ngoài
B15: Nợ đầu kỳ | G15: =F18 -> 212.2416 | H15: =G18 -> 202.45017 | I15: =H18 -> 192.1633 | J15: =I18 -> 181.35591 | K15: =J18 -> 170.00166 | L15: =K18 -> 158.07289 | M15: =L18 -> 145.54053 | N15: =M18 -> 132.37402 | ... U15: =T18 -> 19.542027
B16: Trả lãi vay | G16: =G15*'Thông số'!$I$9 -> 10.739425 | H16: =H15*'Thông số'!$I$9 -> 10.243979 | I16: =I15*'Thông số'!$I$9 -> 9.7234628 | J16: =J15*'Thông số'!$I$9 -> 9.1766089 | K16: =K15*'Thông số'!$I$9 -> 8.6020841 | L16: =L15*'Thông số'!$I$9 -> 7.9984883 | M16: =M15*'Thông số'!$I$9 -> 7.3643507 | N16: =N15*'Thông số'!$I$9 -> 6.6981256 | ... U16: =U15*'Thông số'!$I$9 -> 0.98882656
B17: Trả nợ vay | G17: =-PMT('Thông số'!$I$9,15,$G$15) -> 20.530853 | H17: =-PMT('Thông số'!$I$9,15,$G$15) -> 20.530853 | I17: =-PMT('Thông số'!$I$9,15,$G$15) -> 20.530853 | J17: =-PMT('Thông số'!$I$9,15,$G$15) -> 20.530853 | K17: =-PMT('Thông số'!$I$9,15,$G$15) -> 20.530853 | L17: =-PMT('Thông số'!$I$9,15,$G$15) -> 20.530853 | M17: =-PMT('Thông số'!$I$9,15,$G$15) -> 20.530853 | N17: =-PMT('Thông số'!$I$9,15,$G$15) -> 20.530853 | ... U17: =-PMT('Thông số'!$I$9,15,$G$15) -> 20.530853
B18: Nợ cuối kỳ | F18: ='Thông số'!F9*F8 -> 212.2416 | G18: =G15+G16-G17 -> 202.45017 | H18: =H15+H16-H17 -> 192.1633 | I18: =I15+I16-I17 -> 181.35591 | J18: =J15+J16-J17 -> 170.00166 | K18: =K15+K16-K17 -> 158.07289 | L18: =L15+L16-L17 -> 145.54053 | M18: =M15+M16-M17 -> 132.37402 | N18: =N15+N16-N17 -> 118.5413 | ... U18: =U15+U16-U17 -> 4.2632564e-14
B19: Vay ngân hàng trong nước
B20: Nợ đầu kỳ | G20: =F23 -> 636.7248 | H20: =G23 -> 633.18169 | I20: =H23 -> 629.4051 | J20: =I23 -> 625.37962 | K20: =J23 -> 621.08887 | L20: =K23 -> 616.51536 | M20: =L23 -> 611.64045 | N20: =M23 -> 606.44428 | ... AT20: =AS23 -> 42.689999
B21: Trả lãi vay | G21: =G20*'Thông số'!$I$10 -> 41.960164 | H21: =H20*'Thông số'!$I$10 -> 41.726674 | I21: =I20*'Thông số'!$I$10 -> 41.477796 | J21: =J20*'Thông số'!$I$10 -> 41.212517 | K21: =K20*'Thông số'!$I$10 -> 40.929757 | L21: =L20*'Thông số'!$I$10 -> 40.628362 | M21: =M20*'Thông số'!$I$10 -> 40.307106 | N21: =N20*'Thông số'!$I$10 -> 39.964678 | ... AT21: =AT20*'Thông số'!$I$10 -> 2.8132709
B22: Trả nợ vay | G22: =-PMT('Thông số'!$I$10,40,$G$20) -> 45.50327 | H22: =-PMT('Thông số'!$I$10,40,$G$20) -> 45.50327 | I22: =-PMT('Thông số'!$I$10,40,$G$20) -> 45.50327 | J22: =-PMT('Thông số'!$I$10,40,$G$20) -> 45.50327 | K22: =-PMT('Thông số'!$I$10,40,$G$20) -> 45.50327 | L22: =-PMT('Thông số'!$I$10,40,$G$20) -> 45.50327 | M22: =-PMT('Thông số'!$I$10,40,$G$20) -> 45.50327 | N22: =-PMT('Thông số'!$I$10,40,$G$20) -> 45.50327 | ... AT22: =-PMT('Thông số'!$I$10,40,$G$20) -> 45.50327
B23: Nợ cuối kỳ | F23: ='Thông số'!F10*F8 -> 636.7248 | G23: =G20+G21-G22 -> 633.18169 | H23: =H20+H21-H22 -> 629.4051 | I23: =I20+I21-I22 -> 625.37962 | J23: =J20+J21-J22 -> 621.08887 | K23: =K20+K21-K22 -> 616.51536 | L23: =L20+L21-L22 -> 611.64045 | M23: =M20+M21-M22 -> 606.44428 | N23: =N20+N21-N22 -> 600.90569 | ... AT23: =AT20+AT21-AT22 -> 2.3092639e-12
B25: NGÂN LƯU TÀI TRỢ CỦA CHỦ ĐẦU TƯ (TRIỆU US$)
B26: =B13 -> Năm dự án | C26: =C13 -> 0 | D26: =D13 -> 1 | E26: =E13 -> 2 | F26: =F13 -> 3 | G26: =G13 -> 4 | H26: =H13 -> 5 | I26: =I13 -> 6 | ... AV26: =AV13 -> 45
B27: NCF_Tài trợ của chủ đầu tư (vay nước ngoài) | F27: =F18 -> 212.2416 | G27: =-G17 -> -20.530853 | H27: =-H17 -> -20.530853 | I27: =-I17 -> -20.530853 | J27: =-J17 -> -20.530853 | K27: =-K17 -> -20.530853 | L27: =-L17 -> -20.530853 | M27: =-M17 -> -20.530853 | N27: =-N17 -> -20.530853 | ... U27: =-U17 -> -20.530853
B28: NCF_Ngân hàng nước ngoài | F28: =-F27 -> -212.2416 | G28: =-G27 -> 20.530853 | H28: =-H27 -> 20.530853 | I28: =-I27 -> 20.530853 | J28: =-J27 -> 20.530853 | K28: =-K27 -> 20.530853 | L28: =-L27 -> 20.530853 | M28: =-M27 -> 20.530853 | ... U28: =-U27 -> 20.530853
B29: NCF_Tài trợ của GOJ (vay trong nước) | F29: =F23 -> 636.7248 | G29: =-G22 -> -45.50327 | H29: =-H22 -> -45.50327 | I29: =-I22 -> -45.50327 | J29: =-J22 -> -45.50327 | K29: =-K22 -> -45.50327 | L29: =-L22 -> -45.50327 | M29: =-M22 -> -45.50327 | N29: =-N22 -> -45.50327 | ... AT29: =-AT22 -> -45.50327
B30: NCF_Ngân hàng trong nước | F30: =-F29 -> -636.7248 | G30: =-G29 -> 45.50327 | H30: =-H29 -> 45.50327 | I30: =-I29 -> 45.50327 | J30: =-J29 -> 45.50327 | K30: =-K29 -> 45.50327 | L30: =-L29 -> 45.50327 | M30: =-M29 -> 45.50327 | ... AT30: =-AT29 -> 45.50327
B31: NCF_Tài trợ tổng | F31: =F27+F29 -> 848.9664 | G31: =G27+G29 -> -66.034124 | H31: =H27+H29 -> -66.034124 | I31: =I27+I29 -> -66.034124 | J31: =J27+J29 -> -66.034124 | K31: =K27+K29 -> -66.034124 | L31: =L27+L29 -> -66.034124 | M31: =M27+M29 -> -66.034124 | ... AT31: =AT27+AT29 -> -45.50327
B33: BÁO CÁO THU NHẬP CỦA CHỦ ĐẦU TƯ (TRIỆU J$)
B34: =B6 -> Năm dự án | C34: =C6 -> 0 | D34: =D6 -> 1 | E34: =E6 -> 2 | F34: =F6 -> 3 | G34: =G6 -> 4 | H34: =H6 -> 5 | I34: =I6 -> 6 | ... AV34: =AV6 -> 45
B35: Doanh thu từ thu phí qua cao tốc
B36: Chi phí vận hành cao tốc và trạm thu phí
B37: Trả lãi vay
B38: Lợi nhuận trước thuế
B39: Thuế thu nhập chủ đầu tư phải nộp
B41: PHÂN TÍCH HIỆU QUẢ TÀI CHÍNH CỦA DỰ ÁN (TRIỆU J$)
B42: =B6 -> Năm dự án | C42: =C6 -> 0 | D42: =D6 -> 1 | E42: =E6 -> 2 | F42: =F6 -> 3 | G42: =G6 -> 4 | H42: =H6 -> 5 | I42: =I6 -> 6 | ... AV42: =AV6 -> 45
B43: Ngân lưu vào
B44: Doanh thu từ thu phí qua cao tốc
B45: Giảm chi phí bảo trì các tuyến đường hiện có của GOJ
B46: Giá trị thanh lý cao tốc và trạm thu phí
...

Sheet Phương án 2_Không thu phí
B2: PHƯƠNG ÁN 2: CHÍNH PHỦ SẼ KHÔNG THU PHÍ SAU NĂM 2033
B4: CHỈ SỐ GIÁ
B5: Năm | C5: 2013 | D5: 2014 | E5: 2015 | F5: 2016 | G5: 2017 | H5: 2018 | I5: 2019 | J5: 2020 | K5: 2021 | L5: 2022 | M5: 2023 | N5: 2024 | O5: 2025 | P5: 2026 | Q5: 2027 | R5: 2028 | S5: 2029 | T5: 2030 | U5: 2031 | V5: 2032 | W5: 2033 | X5: 2034 | Y5: 2035 | Z5: 2036 | AA5: 2037 | AB5: 2038 | AC5: 2039 | AD5: 2040 | AE5: 2041 | AF5: 2042 | AG5: 2043 | AH5: 2044 | AI5: 2045 | AJ5: 2046 | AK5: 2047 | AL5: 2048 | AM5: 2049 | AN5: 2050 | AO5: 2051 | AP5: 2052 | AQ5: 2053 | AR5: 2054 | AS5: 2055 | AT5: 2056 | AU5: 2057 | AV5: 2058
B6: Năm dự án | C6: 0 | D6: 1 | E6: 2 | F6: 3 | G6: 4 | H6: 5 | I6: 6 | J6: 7 | K6: 8 | L6: 9 | M6: 10 | N6: 11 | O6: 12 | P6: 13 | Q6: 14 | R6: 15 | S6: 16 | T6: 17 | U6: 18 | V6: 19 | W6: 20 | X6: 21 | Y6: 22 | Z6: 23 | AA6: 24 | AB6: 25 | AC6: 26 | AD6: 27 | AE6: 28 | AF6: 29 | AG6: 30 | AH6: 31 | AI6: 32 | AJ6: 33 | AK6: 34 | AL6: 35 | AM6: 36 | AN6: 37 | AO6: 38 | AP6: 39 | AQ6: 40 | AR6: 41 | AS6: 42 | AT6: 43 | AU6: 44 | AV6: 45
B7: Chỉ số lạm phát trong nước | C7: =(1+'Thông số'!$C$10)^C6 -> 1 | D7: =(1+'Thông số'!$C$10)^D6 -> 1.08 | E7: =(1+'Thông số'!$C$10)^E6 -> 1.1664 | F7: =(1+'Thông số'!$C$10)^F6 -> 1.259712 | G7: =(1+'Thông số'!$C$10)^G6 -> 1.360489 | H7: =(1+'Thông số'!$C$10)^H6 -> 1.4693281 | I7: =(1+'Thông số'!$C$10)^I6 -> 1.5868743 | J7: =(1+'Thông số'!$C$10)^J6 -> 1.7138243 | ... AV7: =(1+'Thông số'!$C$10)^AV6 -> 31.920449
B8: Chỉ số lạm phát nước ngoài | C8: =(1+'Thông số'!$C$11)^C6 -> 1 | D8: =(1+'Thông số'!$C$11)^D6 -> 1.02 | E8: =(1+'Thông số'!$C$11)^E6 -> 1.0404 | F8: =(1+'Thông số'!$C$11)^F6 -> 1.061208 | G8: =(1+'Thông số'!$C$11)^G6 -> 1.0824322 | H8: =(1+'Thông số'!$C$11)^H6 -> 1.1040808 | I8: =(1+'Thông số'!$C$11)^I6 -> 1.1261624 | J8: =(1+'Thông số'!$C$11)^J6 -> 1.1486857 | ... AV8: =(1+'Thông số'!$C$11)^AV6 -> 2.4378542
B9: Tỷ giá hối đối danh nghĩa | C9: ='Thông số'!$C$9*C7/C8 -> 80 | D9: ='Thông số'!$C$9*D7/D8 -> 84.705882 | E9: ='Thông số'!$C$9*E7/E8 -> 89.688581 | F9: ='Thông số'!$C$9*F7/F8 -> 94.96438 | G9: ='Thông số'!$C$9*G7/G8 -> 100.55052 | H9: ='Thông số'!$C$9*H7/H8 -> 106.46526 | I9: ='Thông số'!$C$9*I7/I8 -> 112.72792 | J9: ='Thông số'!$C$9*J7/J8 -> 119.35897 | ... AV9: ='Thông số'!$C$9*AV7/AV8 -> 1047.4933
B10: Chỉ số tăng lưu lượng xe | G10: =(1+'Thông số'!$F$14)^C6 -> 1 | H10: =(1+'Thông số'!$F$14)^D6 -> 1.04 | I10: =(1+'Thông số'!$F$14)^E6 -> 1.0816 | J10: =(1+'Thông số'!$F$14)^F6 -> 1.124864 | K10: =(1+'Thông số'!$F$14)^G6 -> 1.1698586 | L10: =(1+'Thông số'!$F$14)^H6 -> 1.2166529 | M10: =(1+'Thông số'!$F$14)^I6 -> 1.265319 | N10: =(1+'Thông số'!$F$14)^J6 -> 1.3159318 | ... AV10: =(1+'Thông số'!$F$14)^AR6 -> 4.9930615
B12: LỊCH VAY VÀ TRẢ NỢ (TRIỆU US$)
B13: =B6 -> Năm dự án | C13: =C6 -> 0 | D13: =D6 -> 1 | E13: =E6 -> 2 | F13: =F6 -> 3 | G13: =G6 -> 4 | H13: =H6 -> 5 | I13: =I6 -> 6 | ... AV13: =AV6 -> 45
B14: Vay ngân hàng nước ngoài
B15: Nợ đầu kỳ | G15: =F18 -> 212.2416 | H15: =G18 -> 202.45017 | I15: =H18 -> 192.1633 | J15: =I18 -> 181.35591 | K15: =J18 -> 170.00166 | L15: =K18 -> 158.07289 | M15: =L18 -> 145.54053 | N15: =M18 -> 132.37402 | ... U15: =T18 -> 19.542027
B16: Trả lãi vay | G16: =G15*'Thông số'!$I$9 -> 10.739425 | H16: =H15*'Thông số'!$I$9 -> 10.243979 | I16: =I15*'Thông số'!$I$9 -> 9.7234628 | J16: =J15*'Thông số'!$I$9 -> 9.1766089 | K16: =K15*'Thông số'!$I$9 -> 8.6020841 | L16: =L15*'Thông số'!$I$9 -> 7.9984883 | M16: =M15*'Thông số'!$I$9 -> 7.3643507 | N16: =N15*'Thông số'!$I$9 -> 6.6981256 | ... U16: =U15*'Thông số'!$I$9 -> 0.98882656
B17: Trả nợ vay | G17: =-PMT('Thông số'!$I$9,15,$G$15) -> 20.530853 | H17: =-PMT('Thông số'!$I$9,15,$G$15) -> 20.530853 | I17: =-PMT('Thông số'!$I$9,15,$G$15) -> 20.530853 | J17: =-PMT('Thông số'!$I$9,15,$G$15) -> 20.530853 | K17: =-PMT('Thông số'!$I$9,15,$G$15) -> 20.530853 | L17: =-PMT('Thông số'!$I$9,15,$G$15) -> 20.530853 | M17: =-PMT('Thông số'!$I$9,15,$G$15) -> 20.530853 | N17: =-PMT('Thông số'!$I$9,15,$G$15) -> 20.530853 | ... U17: =-PMT('Thông số'!$I$9,15,$G$15) -> 20.530853
B18: Nợ cuối kỳ | F18: ='Thông số'!F9*F8 -> 212.2416 | G18: =G15+G16-G17 -> 202.45017 | H18: =H15+H16-H17 -> 192.1633 | I18: =I15+I16-I17 -> 181.35591 | J18: =J15+J16-J17 -> 170.00166 | K18: =K15+K16-K17 -> 158.07289 | L18: =L15+L16-L17 -> 145.54053 | M18: =M15+M16-M17 -> 132.37402 | N18: =N15+N16-N17 -> 118.5413 | ... U18: =U15+U16-U17 -> 4.2632564e-14
B19: Vay ngân hàng trong nước
B20: Nợ đầu kỳ | G20: =F23 -> 636.7248 | H20: =G23 -> 633.18169 | I20: =H23 -> 629.4051 | J20: =I23 -> 625.37962 | K20: =J23 -> 621.08887 | L20: =K23 -> 616.51536 | M20: =L23 -> 611.64045 | N20: =M23 -> 606.44428 | ... AT20: =AS23 -> 42.689999
B21: Trả lãi vay | G21: =G20*'Thông số'!$I$10 -> 41.960164 | H21: =H20*'Thông số'!$I$10 -> 41.726674 | I21: =I20*'Thông số'!$I$10 -> 41.477796 | J21: =J20*'Thông số'!$I$10 -> 41.212517 | K21: =K20*'Thông số'!$I$10 -> 40.929757 | L21: =L20*'Thông số'!$I$10 -> 40.628362 | M21: =M20*'Thông số'!$I$10 -> 40.307106 | N21: =N20*'Thông số'!$I$10 -> 39.964678 | ... AT21: =AT20*'Thông số'!$I$10 -> 2.8132709
B22: Trả nợ vay | G22: =-PMT('Thông số'!$I$10,40,$G$20) -> 45.50327 | H22: =-PMT('Thông số'!$I$10,40,$G$20) -> 45.50327 | I22: =-PMT('Thông số'!$I$10,40,$G$20) -> 45.50327 | J22: =-PMT('Thông số'!$I$10,40,$G$20) -> 45.50327 | K22: =-PMT('Thông số'!$I$10,40,$G$20) -> 45.50327 | L22: =-PMT('Thông số'!$I$10,40,$G$20) -> 45.50327 | M22: =-PMT('Thông số'!$I$10,40,$G$20) -> 45.50327 | N22: =-PMT('Thông số'!$I$10,40,$G$20) -> 45.50327 | ... AT22: =-PMT('Thông số'!$I$10,40,$G$20) -> 45.50327
B23: Nợ cuối kỳ | F23: ='Thông số'!F10*F8 -> 636.7248 | G23: =G20+G21-G22 -> 633.18169 | H23: =H20+H21-H22 -> 629.4051 | I23: =I20+I21-I22 -> 625.37962 | J23: =J20+J21-J22 -> 621.08887 | K23: =K20+K21-K22 -> 616.51536 | L23: =L20+L21-L22 -> 611.64045 | M23: =M20+M21-M22 -> 606.44428 | N23: =N20+N21-N22 -> 600.90569 | ... AT23: =AT20+AT21-AT22 -> 2.3092639e-12
B25: NGÂN LƯU TÀI TRỢ CỦA CHỦ ĐẦU TƯ (TRIỆU US$)
B26: =B13 -> Năm dự án | C26: =C13 -> 0 | D26: =D13 -> 1 | E26: =E13 -> 2 | F26: =F13 -> 3 | G26: =G13 -> 4 | H26: =H13 -> 5 | I26: =I13 -> 6 | ... AV26: =AV13 -> 45
B27: NCF_Tài trợ của chủ đầu tư (vay nước ngoài) | F27: =F18 -> 212.2416 | G27: =-G17 -> -20.530853 | H27: =-H17 -> -20.530853 | I27: =-I17 -> -20.530853 | J27: =-J17 -> -20.530853 | K27: =-K17 -> -20.530853 | L27: =-L17 -> -20.530853 | M27: =-M17 -> -20.530853 | N27: =-N17 -> -20.530853 | ... U27: =-U17 -> -20.530853
B28: NCF_Ngân hàng nước ngoài | F28: =-F27 -> -212.2416 | G28: =-G27 -> 20.530853 | H28: =-H27 -> 20.530853 | I28: =-I27 -> 20.530853 | J28: =-J27 -> 20.530853 | K28: =-K27 -> 20.530853 | L28: =-L27 -> 20.530853 | M28: =-M27 -> 20.530853 | ... U28: =-U27 -> 20.530853
B29: NCF_Tài trợ của GOJ (vay trong nước) | F29: =F23 -> 636.7248 | G29: =-G22 -> -45.50327 | H29: =-H22 -> -45.50327 | I29: =-I22 -> -45.50327 | J29: =-J22 -> -45.50327 | K29: =-K22 -> -45.50327 | L29: =-L22 -> -45.50327 | M29: =-M22 -> -45.50327 | N29: =-N22 -> -45.50327 | ... AT29: =-AT22 -> -45.50327
B30: NCF_Ngân hàng trong nước | F30: =-F29 -> -636.7248 | G30: =-G29 -> 45.50327 | H30: =-H29 -> 45.50327 | I30: =-I29 -> 45.50327 | J30: =-J29 -> 45.50327 | K30: =-K29 -> 45.50327 | L30: =-L29 -> 45.50327 | M30: =-M29 -> 45.50327 | ... AT30: =-AT29 -> 45.50327
B31: NCF_Tài trợ tổng | F31: =F27+F29 -> 848.9664 | G31: =G27+G29 -> -66.034124 | H31: =H27+H29 -> -66.034124 | I31: =I27+I29 -> -66.034124 | J31: =J27+J29 -> -66.034124 | K31: =K27+K29 -> -66.034124 | L31: =L27+L29 -> -66.034124 | M31: =M27+M29 -> -66.034124 | ... AT31: =AT27+AT29 -> -45.50327
B33: BÁO CÁO THU NHẬP CỦA CHỦ ĐẦU TƯ (TRIỆU J$)
B34: =B6 -> Năm dự án | C34: =C6 -> 0 | D34: =D6 -> 1 | E34: =E6 -> 2 | F34: =F6 -> 3 | G34: =G6 -> 4 | H34: =H6 -> 5 | I34: =I6 -> 6 | ... AV34: =AV6 -> 45
B35: Doanh thu từ thu phí qua cao tốc | G35: ='Thông số'!$F$131*G7*G10 -> 1276.4053 | H35: ='Thông số'!$F$131*H7*H10 -> 1433.6584 | I35: ='Thông số'!$H$131*I7*I10 -> 6925.2786 | J35: ='Thông số'!$H$131*J7*J10 -> 7778.473 | K35: ='Thông số'!$H$131*K7*K10 -> 8736.7808 | L35: ='Thông số'!$H$131*L7*L10 -> 9813.1522 | M35: ='Thông số'!$H$131*M7*M10 -> 11022.133 | N35: ='Thông số'!$H$131*N7*N10 -> 12380.059 | O35: ='Thông số'!$H$131*O7*O10 -> 13905.283 | P35: ='Thông số'!$H$131*P7*P10 -> 15618.413 | ... W35: ='Thông số'!$H$131*W7*W10 -> 35223.83
B36: Chi phí vận hành cao tốc và trạm thu phí | G36: ='Thông số'!$G$103*'Thông số'!$F$16*G7 -> 151.43201 | H36: ='Thông số'!$G$103*'Thông số'!$F$16*H7 -> 163.54658 | I36: ='Thông số'!$G$103*I7 -> 490.63973 | J36: ='Thông số'!$G$103*J7 -> 529.89091 | K36: ='Thông số'!$G$103*K7 -> 572.28218 | L36: ='Thông số'!$G$103*L7 -> 618.06475 | M36: ='Thông số'!$G$103*M7 -> 667.50993 | N36: ='Thông số'!$G$103*N7 -> 720.91073 | O36: ='Thông số'!$G$103*O7 -> 778.58359 | P36: ='Thông số'!$G$103*P7 -> 840.87027 | ... W36: ='Thông số'!$G$103*W7 -> 1441.1039
B37: Trả lãi vay | G37: =G16*G9 -> 1079.8548 | H37: =H16*H9 -> 1090.6278 | I37: =I16*I9 -> 1096.1057 | J37: =J16*J9 -> 1095.3106 | K37: =K16*K9 -> 1087.1322 | L37: =L16*L9 -> 1070.3114 | M37: =M16*M9 -> 1043.4227 | N37: =N16*N9 -> 1004.8534 | ... W37: =W16*W9 -> 0
B38: Lợi nhuận trước thuế | G38: =G35-G36-G37 -> 45.118519 | H38: =H35-H36-H37 -> 179.48404 | I38: =I35-I36-I37 -> 5338.5332 | J38: =J35-J36-J37 -> 6153.2714 | K38: =K35-K36-K37 -> 7077.3665 | L38: =L35-L36-L37 -> 8124.7761 | M38: =M35-M36-M37 -> 9311.1999 | N38: =N35-N36-N37 -> 10654.295 | ... W38: =W35-W36-W37 -> 33782.726
B39: Thuế thu nhập chủ đầu tư phải nộp | G39: =G38*'Thông số'!$G$18 -> 11.27963 | H39: =H38*'Thông số'!$G$18 -> 44.871009 | I39: =I38*'Thông số'!$G$18 -> 1334.6333 | J39: =J38*'Thông số'!$G$18 -> 1538.3179 | K39: =K38*'Thông số'!$G$18 -> 1769.3416 | L39: =L38*'Thông số'!$G$18 -> 2031.194 | M39: =M38*'Thông số'!$G$18 -> 2327.8 | N39: =N38*'Thông số'!$G$18 -> 2663.5738 | ... W39: =W38*'Thông số'!$G$18 -> 8445.6816
B41: PHÂN TÍCH HIỆU QUẢ TÀI CHÍNH CỦA DỰ ÁN (TRIỆU J$)
B42: =B6 -> Năm dự án | C42: =C6 -> 0 | D42: =D6 -> 1 | E42: =E6 -> 2 | F42: =F6 -> 3 | G42: =G6 -> 4 | H42: =H6 -> 5 | I42: =I6 -> 6 | ... AV42: =AV6 -> 45
B43: Ngân lưu vào
B44: Doanh thu từ thu phí qua cao tốc
B45: Giảm chi phí bảo trì các tuyến đường hiện có của GOJ
B46: Giá trị thanh lý cao tốc
...

Sheet Figure
B45: PPP: BOT
B47: Thời gian vận hành + thu phí sau khi hoàn thành việc xây dựng: 15 năm (2019-2033).
B49: Sau đó chuyển giao cho Chính phủ vận hành và bảo dưỡng: 2034-2058.
B51: Tất cả các tính toán được tính theo đơn vị TRIỆU ĐÔLA, và theo giá cố định năm 2013 (NĂM 0).
