Workbook

Sheet PHƯƠNG ÁN
A1: PHƯƠNG ÁN
A2: Phương án 0 - Phương án cơ sở | B2: No concession (Không nhượng bộ) -Không miễn thuế nhập khẩu tàu, thiết bị, vốn lưu động và vật liệu -Không miễn thuế nhiên liệu và thuế VAT đối với các mặt hàng khác -Công ty KHÔNG cư trú => Non-resident company tax = 48% -Không miễn thuế nhập khẩu EU (Import duty for EU = 10%) -Là nước phát triển (Không miễn thuế xuất khẩu 5 %)
A3: Phương án 1 | B3: Miễn thuế nhập khẩu tàu, thiết bị, vốn lưu động và vật liệu (Import duty = 0%)
A4: Phương án 2 | B4: Miễn thuế nhiên liệu và thuế VAT đối với các mặt hàng khác (VAT = Fuel tax = 0%)
A5: Phương án 3 | B5: Là công ty thường trú (Resident company tax = 25%)
A6: Phương án 4 | B6: Là công ty thường trú (Resident company tax = 25%) Miễn thuế nhập khẩu EU (Import duty for EU = 10%)
A7: Phương án 5 | B7: Là công ty thường trú (Resident company tax = 25%) Là đang nước phát triển (Miễn thuế xuất khẩu 5%)
A8: Phương án 6 | B8: Miễn thuế nhập khẩu tàu, thiết bị, vốn lưu động và vật liệu + Miễn thuế nhiên liệu và thuế VAT đối với các mặt hàng khác + Là công ty thường trú + Miễn thuế nhập khẩu EU+ Là nước đang phát triển.

Sheet SUMMARY
B2: PROJECT SUMMARY
C4: MARKET ANALYSIS | H4: TOTAL INVESTMENT POINT OF VIEW (TIPV) | M4: EQUITY POINT OF VIEW - WPTP (EPV) | R4: EFFICIENCY ANALYSIS | W4: REFERENT GROUP ANALYSIS
B5: DISCOUNT RATES | C5: ='Option 0'!D113 -> 0 | D5: ='Option 0'!E113 -> 0.03 | E5: ='Option 0'!F113 -> 0.05 | F5: ='Option 0'!G113 -> 0.08 | G5: ='Option 0'!C113 -> 0.1134281 | H5: ='Option 0'!D118 -> 0 | I5: ='Option 0'!E118 -> 0.03 | J5: ='Option 0'!F118 -> 0.05 | K5: ='Option 0'!G118 -> 0.08 | L5: ='Option 0'!C118 -> 0.1134281 | M5: ='Option 0'!D123 -> 0 | N5: ='Option 0'!E123 -> 0.03 | O5: ='Option 0'!F123 -> 0.05 | P5: ='Option 0'!G123 -> 0.08 | Q5: ='Option 0'!C123 -> 0.1 | R5: ='Option 0'!D195 -> 0 | S5: ='Option 0'!E195 -> 0.03 | T5: ='Option 0'!F195 -> 0.05 | U5: ='Option 0'!G195 -> 0.08 | V5: ='Option 0'!C195 -> 0.1134281 | W5: ='Option 0'!D227 -> 0 | X5: ='Option 0'!E227 -> 0.03 | Y5: ='Option 0'!F227 -> 0.05 | Z5: ='Option 0'!G227 -> 0.08 | AA5: ='Option 0'!C227 -> 0.11
B6: Option 0 | C6: ='Option 0'!D114 -> 0 | D6: ='Option 0'!E114 -> 0 | E6: ='Option 0'!F114 -> 0 | F6: ='Option 0'!G114 -> 0 | G6: ='Option 0'!C114 -> 0 | H6: ='Option 0'!D119 -> 0 | I6: ='Option 0'!E119 -> 0 | J6: ='Option 0'!F119 -> 0 | K6: ='Option 0'!G119 -> 0 | L6: ='Option 0'!C119 -> 0 | M6: ='Option 0'!D124 -> 0 | N6: ='Option 0'!E124 -> 0 | O6: ='Option 0'!F124 -> 0 | P6: ='Option 0'!G124 -> 0 | Q6: ='Option 0'!C124 -> 0 | R6: ='Option 0'!D196 -> 0 | S6: ='Option 0'!E196 -> 0 | T6: ='Option 0'!F196 -> 0 | U6: ='Option 0'!G196 -> 0 | V6: ='Option 0'!C196 -> 0 | W6: ='Option 0'!D228 -> 0 | X6: ='Option 0'!E228 -> 0 | Y6: ='Option 0'!F228 -> 0 | Z6: ='Option 0'!G228 -> 0 | AA6: ='Option 0'!C228 -> 0
B7: Option 1 | C7: =#REF! -> #REF! | D7: =#REF! -> #REF! | E7: =#REF! -> #REF! | F7: =#REF! -> #REF! | G7: =#REF! -> #REF! | H7: =#REF! -> #REF! | I7: =#REF! -> #REF! | J7: =#REF! -> #REF! | ... AA7: =#REF! -> #REF!
B8: Option 2 | C8: =#REF! -> #REF! | D8: =#REF! -> #REF! | E8: =#REF! -> #REF! | F8: =#REF! -> #REF! | G8: =#REF! -> #REF! | H8: =#REF! -> #REF! | I8: =#REF! -> #REF! | J8: =#REF! -> #REF! | ... AA8: =#REF! -> #REF!
B9: Option 3 | C9: =#REF! -> #REF! | D9: =#REF! -> #REF! | E9: =#REF! -> #REF! | F9: =#REF! -> #REF! | G9: =#REF! -> #REF! | H9: =#REF! -> #REF! | I9: =#REF! -> #REF! | J9: =#REF! -> #REF! | ... AA9: =#REF! -> #REF!
B10: Option 4 | C10: =#REF! -> #REF! | D10: =#REF! -> #REF! | E10: =#REF! -> #REF! | F10: =#REF! -> #REF! | G10: =#REF! -> #REF! | H10: =#REF! -> #REF! | I10: =#REF! -> #REF! | J10: =#REF! -> #REF! | ... AA10: =#REF! -> #REF!
B11: Option 5 | C11: =#REF! -> #REF! | D11: =#REF! -> #REF! | E11: =#REF! -> #REF! | F11: =#REF! -> #REF! | G11: =#REF! -> #REF! | H11: =#REF! -> #REF! | I11: =#REF! -> #REF! | J11: =#REF! -> #REF! | ... AA11: =#REF! -> #REF!
B12: Option 6 | C12: =#REF! -> #REF! | D12: =#REF! -> #REF! | E12: =#REF! -> #REF! | F12: =#REF! -> #REF! | G12: =#REF! -> #REF! | H12: =#REF! -> #REF! | I12: =#REF! -> #REF! | J12: =#REF! -> #REF! | ... AA12: =#REF! -> #REF!
B16: IRR | C16: MARKET ANALYSIS | D16: TIPV | E16: EPV | F16: EFFICIENCY ANALYSIS
B17: Option 0 | C17: ='Option 0'!C115 -> #NUM! | D17: ='Option 0'!C120 -> #NUM! | E17: ='Option 0'!C125 -> #NUM! | F17: ='Option 0'!C197 -> #NUM!
B18: Option 1 | C18: =#REF! -> #REF! | D18: =#REF! -> #REF! | E18: =#REF! -> #REF! | F18: =#REF! -> #REF!
B19: Option 2 | C19: =#REF! -> #REF! | D19: =#REF! -> #REF! | E19: =#REF! -> #REF! | F19: =#REF! -> #REF!
B20: Option 3 | C20: =#REF! -> #REF! | D20: =#REF! -> #REF! | E20: =#REF! -> #REF! | F20: =#REF! -> #REF!
B21: Option 4 | C21: =#REF! -> #REF! | D21: =#REF! -> #REF! | E21: =#REF! -> #REF! | F21: =#REF! -> #REF!
B22: Option 5 | C22: =#REF! -> #REF! | D22: =#REF! -> #REF! | E22: =#REF! -> #REF! | F22: =#REF! -> #REF!
B23: Option 6 | C23: =#REF! -> #REF! | D23: =#REF! -> #REF! | E23: =#REF! -> #REF! | F23: =#REF! -> #REF!

Sheet CB_DATA_
A1: Crystal Ball Data
P2: =CB.RecalcCounterFN() -> #NAME?
A3: Workbook Variables | B3: Last Var Column | C3: 0
A4: Name:
A5: Value:
A7: Worksheet Data | B7: Last Data Column Used
B8: 15
A10: Sheet Ref
A11: =CB_DATA_!#REF! -> #REF! | B11: ='Variables 0'!#REF! -> #REF! | C11: ='Option 0'!#REF! -> #REF! | D11: =#REF! -> #REF! | E11: =#REF! -> #REF! | F11: =#REF! -> #REF! | G11: =#REF! -> #REF! | H11: =#REF! -> #REF! | I11: =#REF! -> #REF! | J11: =#REF! -> #REF! | K11: =#REF! -> #REF! | ... O11: =#REF! -> #REF!
A13: Sheet Guid
A14: c2d5e814-2729-4c2c-8c45-17fb8980db1b | B14: 20e0fe2f-a898-4a45-9798-bd04bd92a1d1 | C14: a289cc44-97c0-43d5-8250-87aeaf3c6825 | D14: 83cd0eb9-7279-43dd-bf8d-63a098527715 | E14: db9129c7-e8c0-473b-a33b-47831f946880 | F14: 83a969cd-c32d-4f1e-8c35-124fa8f9710c | G14: bb516a18-9b00-426e-a9c8-e466a8b13c13 | H14: 3780e4a4-c4b9-4c54-b390-ab6807c8e394 | I14: 47cb2232-8573-4d41-80f1-79deedab87bd | J14: 6db9b7a4-dfec-47e3-b5f9-f749d03771c8 | K14: 3f040fd4-cf6e-45aa-bc40-455f1f66e102 | L14: 5c7af43d-9427-43a3-9170-1906e148aad0 | M14: d849a4ce-9947-4f04-8932-cb7c339b3f89 | N14: 04675f9f-2773-4303-8fec-7c95e094ddd1 | O14: c635650f-02f1-49a4-9216-ee14733901cb
A16: Deleted sheet count
A19: Last row used
A20: 31 | B20: 31 | C20: 31 | D20: 31 | E20: 31 | F20: 31 | G20: 31 | H20: 31 | I20: 31 | J20: 31 | K20: 31 | L20: 31 | M20: 31 | N20: 31 | O20: 31
A25: Data blocks
A26: CB_Block_0 | B26: CB_Block_7.0.0.0:1 | C26: CB_Block_7.0.0.0:1 | D26: CB_Block_7.0.0.0:1 | E26: CB_Block_7.0.0.0:1 | F26: CB_Block_7.0.0.0:1 | G26: CB_Block_7.0.0.0:1 | H26: CB_Block_7.0.0.0:1 | I26: CB_Block_7.0.0.0:1 | J26: CB_Block_7.0.0.0:1 | K26: CB_Block_7.0.0.0:1 | L26: CB_Block_7.0.0.0:1 | M26: CB_Block_7.0.0.0:1 | N26: CB_Block_7.0.0.0:1 | O26: CB_Block_7.0.0.0:1
