Workbook

Sheet Phương án 1
A2: DỰ ÁN CẤP NƯỚC ĐÔ THỊ Ở ĐÔNG NAM QUEENSLAND
A3: HAI PHƯƠNG ÁN PHƯƠNG ÁN 1: DWR TỪ CHỐI ĐỀ XUẤT CỦA AV VÀ THỰC HIỆN DỰ ÁN ĐẬP TRÊN SÔNG ELIZABETH PHƯƠNG ÁN 2: DWR CHẤP THUẬN DỰ ÁN XÂY NHÀ MÁY KHỬ MUỐI CỦA AV
A5: Vòng đời | B5: Năm | D5: CHI PHÍ ĐẦU TƯ BAN ĐẦU (2009-2010) - Triệu $
A6: Vòng đời dự án | B6: 49 | D6: Đầu tư cố định | F6: Giá trị tài chính (sau VAT/thuế lương) | G6: Thuế VAT/lương | H6: Giá trị tài chính (trước VAT/thuế lương) | I6: Giá trị kinh tế
D7: Hệ thống kết nối đập | F7: 850 | G7: =F7-H7 -> 16.666667 | H7: =F7/(1+B20) -> 833.33333 | I7: =H7 -> 833.33333
A8: Công suất | B8: (ML/a) | D8: Đường ống và trạm bơm | F8: 355 | G8: =F8-H8 -> 6.9607843 | H8: =F8/(1+$B$20) -> 348.03922 | I8: =H8 -> 348.03922
A9: 2011-2024 | B9: 90000 | D9: Nhà máy xử lý nước
A10: 2025-2058 | B10: =B9+54000 -> 144000 | D10: Nhà máy | F10: 12 | G10: =F10-H10 -> 0.23529412 | H10: =F10/(1+$B$20) -> 11.764706 | I10: =H10 -> 11.764706
D11: Thiết bị | F11: 50 | G11: =F11-H11 -> 0.98039216 | H11: =F11/(1+$B$20) -> 49.019608 | I11: =H11 -> 49.019608
D12: Hồ chứa | F12: 5 | G12: =F12-H12 -> 0.098039216 | H12: =F12/(1+$B$20) -> 4.9019608 | I12: =H12 -> 4.9019608
A13: Hệ số tăng chi phí năng lượng | D13: Tổng | F13: =SUM(F7:F12) -> 1272 | G13: =SUM(G7:G12) -> 24.941176 | H13: =SUM(H7:H12) -> 1247.0588 | I13: =SUM(I7:I12) -> 1247.0588
A14: 2012-2034 | B14: 0.01
A15: 2035-2058 | B15: 0 | D15: CHI PHÍ HOẠT ĐỘNG (TỪ NĂM 2011)
E16: Tỉ lệ | F16: Giá trị tài chính (sau VAT/thuế lương) | G16: Thuế VAT/lương | H16: Giá trị tài chính (trước VAT/thuế lương) | I16: Giá trị kinh tế
A17: Các mức thuế suất và giá ẩn | B17: % | D17: Cố định ($ million/pa) | F17: 18
A18: Giá ẩn lao động không kỹ năng | B18: 0.26 | D18: Lương nhân viên, nhân công | E18: 0.4 | F18: =$F$17*E18 -> 7.2 | G18: =F18-H18 -> 0.20970874 | H18: =F18/(1+B21) -> 6.9902913 | I18: =H18 -> 6.9902913
A19: Thuế VAT | B19: 0.1 | D19: Năng lượng | E19: 0.1 | F19: =$F$17*E19 -> 1.8 | G19: =F19-H19 -> 0.16363636 | H19: =F19/(1+$B$19) -> 1.6363636 | I19: =H19 -> 1.6363636
A20: Thuế VAT (chi phí vốn) | B20: 0.02 | D20: Nguyên vật liệu | E20: 0.5 | F20: =$F$17*E20 -> 9 | G20: =F20-H20 -> 0.81818182 | H20: =F20/(1+$B$19) -> 8.1818182 | I20: =H20 -> 8.1818182
A21: Thuế lương | B21: 0.03 | D21: Biến đổi ($/ML) | F21: 225
D22: Lương nhân viên, nhân công | E22: 0.4 | F22: =$F$21*E22 -> 90 | G22: =F22-H22 -> 2.6213592 | H22: =F22/(1+B21) -> 87.378641 | I22: =H22 -> 87.378641
A23: Chi phí ngoại tác | B23: (triệu $/a) | D23: Năng lượng | E23: 0.1 | F23: =$F$21*E23 -> 22.5 | G23: =F23-H23 -> 2.0454545 | H23: =F23/(1+B19) -> 20.454545 | I23: =H23 -> 20.454545
A24: Môi trường | B24: 40 | D24: Nguyên vật liệu | E24: 0.5 | F24: =$F$21*E24 -> 112.5 | G24: =F24-H24 -> 10.227273 | H24: =F24/(1+B19) -> 102.27273 | I24: =H24 -> 102.27273
A26: Khác | D26: VỐN NÂNG CẤP (TRIỆU $)
A27: Lạm phát | B27: 0 | D27: Đầu tư cố định | F27: Giá trị tài chính (sau VAT) | G27: Thuế VAT | H27: Giá trị tài chính (trước VAT) | I27: Giá trị kinh tế
A28: Suất chiết khấu | B28: 0.06 | D28: 2013 | F28: 0.14 | G28: =F28-H28 -> 0.002745098 | H28: =F28/(1+$B$20) -> 0.1372549 | I28: =H28 -> 0.1372549
A29: Hệ số chuyển đổi | B29: 1000000 | D29: 2018 | F29: 0.85 | G29: =F29-H29 -> 0.016666667 | H29: =F29/(1+$B$20) -> 0.83333333 | I29: =H29 -> 0.83333333
A30: Giá sẵn lòng trả | B30: 5250 | C30: $/ML | D30: 2023 | F30: 0.6 | G30: =F30-H30 -> 0.011764706 | H30: =F30/(1+$B$20) -> 0.58823529 | I30: =H30 -> 0.58823529
D31: 2028 | F31: 2.2 | G31: =F31-H31 -> 0.043137255 | H31: =F31/(1+$B$20) -> 2.1568627 | I31: =H31 -> 2.1568627
D32: 2033 | F32: 0.33 | G32: =F32-H32 -> 0.0064705882 | H32: =F32/(1+$B$20) -> 0.32352941 | I32: =H32 -> 0.32352941
D33: 2035-2058 | F33: 20 | G33: =F33-H33 -> 0.39215686 | H33: =F33/(1+$B$20) -> 19.607843 | I33: =H33 -> 19.607843
D34: Tổng | F34: =SUM(F28:F33) -> 24.12 | G34: =SUM(G28:G33) -> 0.47294118 | H34: =SUM(H28:H33) -> 23.647059 | I34: =SUM(I28:I33) -> 23.647059

Sheet Phân tích phương án 1
A1: Năm | B1: 2009 | C1: 2010 | D1: 2011 | E1: 2012 | F1: 2013 | G1: 2014 | H1: 2015 | I1: 2016 | J1: 2017 | K1: 2018 | L1: 2019 | M1: 2020 | N1: 2021 | O1: 2022 | P1: 2023 | Q1: 2024 | R1: 2025 | S1: 2026 | T1: 2027 | U1: 2028 | V1: 2029 | W1: 2030 | X1: 2031 | Y1: 2032 | Z1: 2033 | AA1: 2034 | AB1: 2035 | AC1: 2036 | AD1: 2037 | AE1: 2038 | AF1: 2039 | AG1: 2040 | AH1: 2041 | AI1: 2042 | AJ1: 2043 | AK1: 2044 | AL1: 2045 | AM1: 2046 | AN1: 2047 | AO1: 2048 | AP1: 2049 | AQ1: 2050 | AR1: 2051 | AS1: 2052 | AT1: 2053 | AU1: 2054 | AV1: 2055 | AW1: 2056 | AX1: 2057 | AY1: 2058
A3: CHỈ SỐ GIÁ
A5: Năm | B5: 0 | C5: 1 | D5: 2 | E5: 3 | F5: 4 | G5: 5 | H5: 6 | I5: 7 | J5: 8 | K5: 9 | L5: 10 | M5: 11 | N5: 12 | O5: 13 | P5: 14 | Q5: 15 | R5: 16 | S5: 17 | T5: 18 | U5: 19 | V5: 20 | W5: 21 | X5: 22 | Y5: 23 | Z5: 24 | AA5: 25 | AB5: 26 | AC5: 27 | AD5: 28 | AE5: 29 | AF5: 30 | AG5: 31 | AH5: 32 | AI5: 33 | AJ5: 34 | AK5: 35 | AL5: 36 | AM5: 37 | AN5: 38 | AO5: 39 | AP5: 40 | AQ5: 41 | AR5: 42 | AS5: 43 | AT5: 44 | AU5: 45 | AV5: 46 | AW5: 47 | AX5: 48 | AY5: 49
A6: Mức giá chung | B6: =(1+'Phương án 1'!$B$27)^B5 -> 1 | C6: =(1+'Phương án 1'!$B$27)^C5 -> 1 | D6: =(1+'Phương án 1'!$B$27)^D5 -> 1 | E6: =(1+'Phương án 1'!$B$27)^E5 -> 1 | F6: =(1+'Phương án 1'!$B$27)^F5 -> 1 | G6: =(1+'Phương án 1'!$B$27)^G5 -> 1 | H6: =(1+'Phương án 1'!$B$27)^H5 -> 1 | I6: =(1+'Phương án 1'!$B$27)^I5 -> 1 | ... AY6: =(1+'Phương án 1'!$B$27)^AY5 -> 1
A7: Giá năng lượng | D7: =(1+'Phương án 1'!$B$27+'Phương án 1'!$B$14)^B5 -> 1 | E7: =(1+'Phương án 1'!$B$27+'Phương án 1'!$B$14)^C5 -> 1.01 | F7: =(1+'Phương án 1'!$B$27+'Phương án 1'!$B$14)^D5 -> 1.0201 | G7: =(1+'Phương án 1'!$B$27+'Phương án 1'!$B$14)^E5 -> 1.030301 | H7: =(1+'Phương án 1'!$B$27+'Phương án 1'!$B$14)^F5 -> 1.040604 | I7: =(1+'Phương án 1'!$B$27+'Phương án 1'!$B$14)^G5 -> 1.0510101 | J7: =(1+'Phương án 1'!$B$27+'Phương án 1'!$B$14)^H5 -> 1.0615202 | K7: =(1+'Phương án 1'!$B$27+'Phương án 1'!$B$14)^I5 -> 1.0721354 | ... AA7: =(1+'Phương án 1'!$B$27+'Phương án 1'!$B$14)^Y5 -> 1.257163 | AB7: =(1+'Phương án 1'!$B$27+'Phương án 1'!$B$15)^AB6 -> 1 | AC7: =(1+'Phương án 1'!$B$27+'Phương án 1'!$B$15)^AC6 -> 1 | AD7: =(1+'Phương án 1'!$B$27+'Phương án 1'!$B$15)^AD6 -> 1 | AE7: =(1+'Phương án 1'!$B$27+'Phương án 1'!$B$15)^AE5 -> 1 | AF7: =(1+'Phương án 1'!$B$27+'Phương án 1'!$B$15)^AF5 -> 1 | AG7: =(1+'Phương án 1'!$B$27+'Phương án 1'!$B$15)^AG5 -> 1 | AH7: =(1+'Phương án 1'!$B$27+'Phương án 1'!$B$15)^AH5 -> 1 | AI7: =(1+'Phương án 1'!$B$27+'Phương án 1'!$B$15)^AI5 -> 1 | AJ7: =(1+'Phương án 1'!$B$27+'Phương án 1'!$B$15)^AJ5 -> 1 | AK7: =(1+'Phương án 1'!$B$27+'Phương án 1'!$B$15)^AK5 -> 1 | AL7: =(1+'Phương án 1'!$B$27+'Phương án 1'!$B$15)^AL5 -> 1 | ... AY7: =(1+'Phương án 1'!$B$27+'Phương án 1'!$B$15)^AY5 -> 1
A9: CÔNG SUẤT
AY10: Đơn vị: ML/a
A11: Năm | B11: =B5 -> 0 | C11: =C5 -> 1 | D11: =D5 -> 2 | E11: =E5 -> 3 | F11: =F5 -> 4 | G11: =G5 -> 5 | H11: =H5 -> 6 | I11: =I5 -> 7 | ... AY11: =AY5 -> 49
A12: Công suất | D12: ='Phương án 1'!$B$9 -> 90000 | E12: ='Phương án 1'!$B$9 -> 90000 | F12: ='Phương án 1'!$B$9 -> 90000 | G12: ='Phương án 1'!$B$9 -> 90000 | H12: ='Phương án 1'!$B$9 -> 90000 | I12: ='Phương án 1'!$B$9 -> 90000 | J12: ='Phương án 1'!$B$9 -> 90000 | K12: ='Phương án 1'!$B$9 -> 90000 | ... Q12: ='Phương án 1'!$B$9 -> 90000 | R12: ='Phương án 1'!$B$10 -> 144000 | S12: ='Phương án 1'!$B$10 -> 144000 | T12: ='Phương án 1'!$B$10 -> 144000 | U12: ='Phương án 1'!$B$10 -> 144000 | V12: ='Phương án 1'!$B$10 -> 144000 | W12: ='Phương án 1'!$B$10 -> 144000 | X12: ='Phương án 1'!$B$10 -> 144000 | Y12: ='Phương án 1'!$B$10 -> 144000 | ... AY12: ='Phương án 1'!$B$10 -> 144000
A15: BÁO CÁO NGÂN LƯU QUAN ĐIỂM DWR
AY16: Đơn vị: Triệu VNĐ
A17: Năm | B17: =B5 -> 0 | C17: =C5 -> 1 | D17: =D5 -> 2 | E17: =E5 -> 3 | F17: =F5 -> 4 | G17: =G5 -> 5 | H17: =H5 -> 6 | I17: =I5 -> 7 | ... AY17: =AY5 -> 49
A18: Ngân lưu ra
A19: Đầu tư ban đầu
A20: VAT @2%
A21: Chi phí cố định
A22: Lương nhân viên, nhân công
A23: Thuế lương @3%
A24: Năng lượng
A25: VAT @10%
A26: Nguyên vật liệu
A27: VAT @10%
A28: Chi phí biến đổi
A29: Lương nhân viên, nhân công
... A34: VAT @10%
A35: Cải thiện vốn | F35: ='Phương án 1'!$H$28*'Phân tích phương án 1'!F6 -> 0.1372549 | K35: ='Phương án 1'!$H$29*'Phân tích phương án 1'!K6 -> 0.83333333 | P35: ='Phương án 1'!$H$30*'Phân tích phương án 1'!P6 -> 0.58823529 | U35: ='Phương án 1'!$H$31*'Phân tích phương án 1'!U6 -> 2.1568627 | Z35: ='Phương án 1'!$H$32*'Phân tích phương án 1'!Z6 -> 0.32352941 | AB35: ='Phương án 1'!$H$33*AB6 -> 19.607843 | AC35: ='Phương án 1'!$H$33*AC6 -> 19.607843 | AD35: ='Phương án 1'!$H$33*AD6 -> 19.607843 | AE35: ='Phương án 1'!$H$33*AE6 -> 19.607843 | AF35: ='Phương án 1'!$H$33*AF6 -> 19.607843 | AG35: ='Phương án 1'!$H$33*AG6 -> 19.607843 | AH35: ='Phương án 1'!$H$33*AH6 -> 19.607843 | AI35: ='Phương án 1'!$H$33*AI6 -> 19.607843 | ... AY35: ='Phương án 1'!$H$33*AY6 -> 19.607843
A36: VAT @2% | F36: ='Phương án 1'!$G$28*F6 -> 0.002745098 | K36: ='Phương án 1'!$G$29*K6 -> 0.016666667 | P36: ='Phương án 1'!$G$30*P6 -> 0.011764706 | U36: ='Phương án 1'!$G$31*U6 -> 0.043137255 | Z36: ='Phương án 1'!$G$32*Z6 -> 0.0064705882 | AB36: ='Phương án 1'!$G$33*AB6 -> 0.39215686 | AC36: ='Phương án 1'!$G$33*AC6 -> 0.39215686 | AD36: ='Phương án 1'!$G$33*AD6 -> 0.39215686 | AE36: ='Phương án 1'!$G$33*AE6 -> 0.39215686 | AF36: ='Phương án 1'!$G$33*AF6 -> 0.39215686 | AG36: ='Phương án 1'!$G$33*AG6 -> 0.39215686 | AH36: ='Phương án 1'!$G$33*AH6 -> 0.39215686 | AI36: ='Phương án 1'!$G$33*AI6 -> 0.39215686 | ... AY36: ='Phương án 1'!$G$33*AY6 -> 0.39215686
A37: Tổng | B37: =SUM(B19:B20,B21,B28,B35:B36) -> 0 | C37: =SUM(C19:C20,C21,C28,C35:C36) -> 0 | D37: =SUM(D19:D20,D21,D28,D35:D36) -> 0 | E37: =SUM(E19:E20,E21,E28,E35:E36) -> 0 | F37: =SUM(F19:F20,F21,F28,F35:F36) -> 0.14 | G37: =SUM(G19:G20,G21,G28,G35:G36) -> 0 | H37: =SUM(H19:H20,H21,H28,H35:H36) -> 0 | I37: =SUM(I19:I20,I21,I28,I35:I36) -> 0 | ... AY37: =SUM(AY19:AY20,AY21,AY28,AY35:AY36) -> 20
A39: Nộp thuế
A40: Thuế VAT phải nộp (+) / hoàn lại (-) | B40: =-SUM(B20,B25,B27,B32,B34,B36)+SUM(B23,B30) -> 0 | C40: =-SUM(C20,C25,C27,C32,C34,C36)+SUM(C23,C30) -> 0 | D40: =-SUM(D20,D25,D27,D32,D34,D36)+SUM(D23,D30) -> 0 | E40: =-SUM(E20,E25,E27,E32,E34,E36)+SUM(E23,E30) -> 0 | F40: =-SUM(F20,F25,F27,F32,F34,F36)+SUM(F23,F30) -> -0.002745098 | G40: =-SUM(G20,G25,G27,G32,G34,G36)+SUM(G23,G30) -> 0 | H40: =-SUM(H20,H25,H27,H32,H34,H36)+SUM(H23,H30) -> 0 | I40: =-SUM(I20,I25,I27,I32,I34,I36)+SUM(I23,I30) -> 0 | ... AY40: =-SUM(AY20,AY25,AY27,AY32,AY34,AY36)+SUM(AY23,AY30) -> -0.39215686
A42: NCF (DWR, sau thuế) | B42: =B37+B40 -> 0 | C42: =C37+C40 -> 0 | D42: =D37+D40 -> 0 | E42: =E37+E40 -> 0 | F42: =F37+F40 -> 0.1372549 | G42: =G37+G40 -> 0 | H42: =H37+H40 -> 0 | I42: =I37+I40 -> 0 | ... AY42: =AY37+AY40 -> 19.607843
A44: Suất chiết khấu | B44: ='Phương án 1'!B28 -> 0.06
A45: NPV_Chi phí DWR | B45: =NPV($B$44,$C$42:$AA$42)+$B$42 -> 1.6549205
A46: Phân tích hiệu quả - chi phí ($/ML) | B46: =B45/SUM(B12:AA12)*'Phương án 1'!B29 -> 0.61293353
A49: PHÂN TÍCH HIỆU QUẢ KINH TẾ | AZ49: -
AZ50: -
A51: Năm | B51: =B5 -> 0 | C51: =C5 -> 1 | D51: =D5 -> 2 | E51: =E5 -> 3 | F51: =F5 -> 4 | G51: =G5 -> 5 | H51: =H5 -> 6 | I51: =I5 -> 7 | ... AY51: =AY5 -> 49 | AZ51: -
A52: Chi phí | AZ52: -
A53: Đầu tư ban đầu | AZ53: -
A54: Chi phí cố định | AZ54: -
...

Sheet Phương án 2
A2: DỰ ÁN CẤP NƯỚC ĐÔ THỊ Ở ĐÔNG NAM QUEENSLAND
A3: HAI PHƯƠNG ÁN PHƯƠNG ÁN 1: DWR TỪ CHỐI ĐỀ XUẤT CỦA AV VÀ THỰC HIỆN DỰ ÁN ĐẬP TRÊN SÔNG ELIZABETH PHƯƠNG ÁN 2: DWR CHẤP THUẬN ĐỀ XUẤT CỦA AV VÀ XÂY DỰNG HỆ THỐNG NHÀ MÁY KHỬ MUỐI
A5: Vòng đời | B5: Năm | D5: Các mức thuế suất và giá ẩn | E5: % | G5: Khác
A6: Vòng đời dự án | B6: 49 | D6: Giá ẩn lao động không kỹ năng | E6: 0.26 | G6: Lạm phát | H6: 0
A7: Đường hầm và cơ sở hạ tầng biển | B7: 40 | D7: Thuế TNDN | E7: 0.3 | G7: Suất chiết khấu | H7: 0.06
A8: Nhà máy, công trình và thiết bị | B8: 30 | D8: Thuế VAT | E8: 0.1 | G8: Hệ số chuyển đổi | H8: 1000000
A9: Đường ống, máy bơm và hồ chứa | B9: 25 | D9: Thuế VAT (đầu tư ban đầu) | E9: 0.02
D10: Thuế lương | E10: 0.03 | G10: Chi phí ngoại tác | H10: ($/ML)
A11: Công suất | B11: (ML/pa) | G11: Môi trường | H11: 400
A12: 2011-2016 | B12: 36000 | D12: Cơ cấu vốn | E12: =E13+E17 -> 510
A13: 2017-2022 | B13: =B12*2 -> 72000 | D13: Vốn vay | E13: 500 | G13: Vốn nâng cấp | H13: Giá trị tài chính (sau VAT) | I13: Thuế VAT | J13: Giá trị tài chính (trước VAT) | K13: Giá trị kinh tế
A14: 2023-2028 | B14: =B12*3 -> 108000 | D14: Lãi suất (thực) | E14: 0.08 | G14: 2035-2058 | H14: 20 | I14: =H14-J14 -> 0.39215686 | J14: =H14/(1+E9) -> 19.607843 | K14: =J14 -> 19.607843 | L14: (triệu $/a)
A15: 2029-2058 | B15: =B12*4 -> 144000 | D15: Lãi suất (dn) | E15: =(E14+1)*(H6+1)-1 -> 0.08
D16: Thời gian trả nợ | E16: 15 | G16: DWR | I16: Đơn vị | J16: Giai đoạn
D17: Vốn chủ sỡ hữu | E17: =B29-E13 -> 10 | G17: Bán nước | H17: 5250 | I17: $/ML | J17: 2011-2034
A18: Hệ số tăng chi phí năng lượng | D18: re (thực) | E18: 0.09 | G18: Bán nhà máy | H18: 100 | I18: Triệu $ | J18: 2034
A19: 2012-2034 | B19: 0.01 | D19: WACC | E19: =(E13/E12*E14)+(E17/E12*E18) -> 0.080196078
A20: 2035-2058 | B20: 0
A22: CHI PHÍ ĐẦU TƯ BAN ĐẦU
A23: Năm | B23: 2009 | C23: 2010 | D23: 2015 | E23: 2016 | F23: 2021 | G23: 2022 | H23: 2027 | I23: 2028
A24: TÀI CHÍNH (TRIỆU $) | B24: Nhà máy 1 | D24: Nhà máy 2 | F24: Nhà mày 3 | H24: Nhà máy 4
A25: Đường hầm và cơ sở hạ tầng biển | B25: 160 | C25: 160 | F25: 160 | G25: 160 | J25: =SUM(B25:I25) -> 640
A26: Nhà máy, công trình, thiết bị | B26: 250 | C26: 250 | D26: 176 | E26: 176 | F26: 250 | G26: 250 | H26: 176 | I26: 176 | J26: =SUM(B26:I26) -> 1704
A27: Chi phí đất | B27: 5 | F27: 5 | J27: =SUM(B27:I27) -> 10
A28: Đường ống, máy bơm, hồ chứa | B28: 95 | C28: 95 | F28: 95 | G28: 95 | J28: =SUM(B28:I28) -> 380
A29: Tổng | B29: =SUM(B25:B28) -> 510 | C29: =SUM(C25:C28) -> 505 | D29: =SUM(D25:D28) -> 176 | E29: =SUM(E25:E28) -> 176 | F29: =SUM(F25:F28) -> 510 | G29: =SUM(G25:G28) -> 505 | H29: =SUM(H25:H28) -> 176 | I29: =SUM(I25:I28) -> 176 | J29: =SUM(J25:J28) -> 2734
A30: KINH TẾ (TRIỆU $) | B30: Nhà máy 1 | D30: Nhà máy 2 | F30: Nhà mày 3 | H30: Nhà máy 4
A31: Đường hầm và cơ sở hạ tầng biển | B31: =B25/(1+$E$9) -> 156.86275 | C31: =C25/(1+$E$9) -> 156.86275 | F31: =F25/(1+$E$9) -> 156.86275 | G31: =G25/(1+$E$9) -> 156.86275 | J31: =SUM(B31:I31) -> 627.45098
A32: Nhà máy, công trình, thiết bị | B32: =B26/(1+$E$9) -> 245.09804 | C32: =C26/(1+$E$9) -> 245.09804 | D32: =D26/(1+$E$9) -> 172.54902 | E32: =E26/(1+$E$9) -> 172.54902 | F32: =F26/(1+$E$9) -> 245.09804 | G32: =G26/(1+$E$9) -> 245.09804 | H32: =H26/(1+$E$9) -> 172.54902 | I32: =I26/(1+$E$9) -> 172.54902 | J32: =SUM(B32:I32) -> 1670.5882
A33: Chi phí đất | B33: =B27/(1+$E$9) -> 4.9019608 | F33: =F27/(1+$E$9) -> 4.9019608 | J33: =SUM(B33:I33) -> 9.8039216
A34: Đường ống, máy bơm, hồ chứa | B34: =B28/(1+$E$9) -> 93.137255 | C34: =C28/(1+$E$9) -> 93.137255 | F34: =F28/(1+$E$9) -> 93.137255 | G34: =G28/(1+$E$9) -> 93.137255 | J34: =SUM(B34:I34) -> 372.54902
A35: Tổng | B35: =SUM(B31:B34) -> 500 | C35: =SUM(C31:C34) -> 495.09804 | D35: =SUM(D31:D34) -> 172.54902 | E35: =SUM(E31:E34) -> 172.54902 | F35: =SUM(F31:F34) -> 500 | G35: =SUM(G31:G34) -> 495.09804 | H35: =SUM(H31:H34) -> 172.54902 | I35: =SUM(I31:I34) -> 172.54902 | J35: =SUM(J31:J34) -> 2680.3922
A36: THUẾ VAT | B36: =B29-B35 -> 10 | C36: =C29-C35 -> 9.9019608 | D36: =D29-D35 -> 3.4509804 | E36: =E29-E35 -> 3.4509804 | F36: =F29-F35 -> 10 | G36: =G29-G35 -> 9.9019608 | H36: =H29-H35 -> 3.4509804 | I36: =I29-I35 -> 3.4509804
A38: CHI PHÍ HOẠT ĐỘNG (TỪ NĂM 2011)
A39: Nhà máy 1 và 3 | B39: Tỉ lệ | C39: Giá trị tài chính (sau VAT/tiền lương) | D39: Thuế VAT/tiền lương | E39: Giá trị tài chính (trước VAT/tiền lương) | F39: Giá trị kinh tế
A40: Cố định ($ million/pa) | C40: 22 | F40: =SUM(F41:F43) -> 20.8
A41: Lương nhân viên, nhân công | B41: 0.4 | C41: =$C$40*B41 -> 8.8 | E41: =C41 -> 8.8 | F41: =E41 -> 8.8
A42: Năng lượng | B42: 0.3 | C42: =$C$40*B42 -> 6.6 | D42: =C42-E42 -> 0.6 | E42: =C42/(1+$E$8) -> 6 | F42: =E42 -> 6
A43: Nguyên vật liệu | B43: 0.3 | C43: =$C$40*B43 -> 6.6 | D43: =C43-E43 -> 0.6 | E43: =C43/(1+$E$8) -> 6 | F43: =E43 -> 6
A44: Biến đổi ($/ML) | C44: 350 | F44: =SUM(F45:F47) -> 330.90909
...

Sheet Phân tích phương án 2
A1: Năm | B1: 2009 | C1: 2010 | D1: 2011 | E1: 2012 | F1: 2013 | G1: 2014 | H1: 2015 | I1: 2016 | J1: 2017 | K1: 2018 | L1: 2019 | M1: 2020 | N1: 2021 | O1: 2022 | P1: 2023 | Q1: 2024 | R1: 2025 | S1: 2026 | T1: 2027 | U1: 2028 | V1: 2029 | W1: 2030 | X1: 2031 | Y1: 2032 | Z1: 2033 | AA1: 2034 | AB1: 2035 | AC1: 2036 | AD1: 2037 | AE1: 2038 | AF1: 2039 | AG1: 2040 | AH1: 2041 | AI1: 2042 | AJ1: 2043 | AK1: 2044 | AL1: 2045 | AM1: 2046 | AN1: 2047 | AO1: 2048 | AP1: 2049 | AQ1: 2050 | AR1: 2051 | AS1: 2052 | AT1: 2053 | AU1: 2054 | AV1: 2055 | AW1: 2056 | AX1: 2057 | AY1: 2058
AZ2: -
A3: LỊCH VAY VÀ TRẢ NỢ | AZ3: -
Q4: Đơn vị: Triệu VNĐ | AZ4: -
A5: Năm | B5: 0 | C5: 1 | D5: 2 | E5: 3 | F5: 4 | G5: 5 | H5: 6 | I5: 7 | J5: 8 | K5: 9 | L5: 10 | M5: 11 | N5: 12 | O5: 13 | P5: 14 | Q5: 15 | AZ5: -
A6: Nợ đầu kỳ | C6: =B11 -> 500 | D6: =C11 -> 481.58523 | E6: =D11 -> 461.69727 | F6: =E11 -> 440.21828 | G6: =F11 -> 417.02097 | H6: =G11 -> 391.96788 | I6: =H11 -> 364.91054 | J6: =I11 -> 335.68861 | ... Q6: =P11 -> 54.087752 | AZ6: -
A7: Lãi phát sinh | C7: =C6*'Phương án 2'!$E$15 -> 40 | D7: =D6*'Phương án 2'!$E$15 -> 38.526818 | E7: =E6*'Phương án 2'!$E$15 -> 36.935782 | F7: =F6*'Phương án 2'!$E$15 -> 35.217463 | G7: =G6*'Phương án 2'!$E$15 -> 33.361678 | H7: =H6*'Phương án 2'!$E$15 -> 31.35743 | I7: =I6*'Phương án 2'!$E$15 -> 29.192843 | J7: =J6*'Phương án 2'!$E$15 -> 26.855089 | ... Q7: =Q6*'Phương án 2'!$E$15 -> 4.3270202 | AZ7: -
A8: Trả nợ | C8: =-PMT('Phương án 2'!$E$15,'Phương án 2'!$E$16,$C$6) -> 58.414772 | D8: =-PMT('Phương án 2'!$E$15,'Phương án 2'!$E$16,$C$6) -> 58.414772 | E8: =-PMT('Phương án 2'!$E$15,'Phương án 2'!$E$16,$C$6) -> 58.414772 | F8: =-PMT('Phương án 2'!$E$15,'Phương án 2'!$E$16,$C$6) -> 58.414772 | G8: =-PMT('Phương án 2'!$E$15,'Phương án 2'!$E$16,$C$6) -> 58.414772 | H8: =-PMT('Phương án 2'!$E$15,'Phương án 2'!$E$16,$C$6) -> 58.414772 | I8: =-PMT('Phương án 2'!$E$15,'Phương án 2'!$E$16,$C$6) -> 58.414772 | J8: =-PMT('Phương án 2'!$E$15,'Phương án 2'!$E$16,$C$6) -> 58.414772 | ... Q8: =-PMT('Phương án 2'!$E$15,'Phương án 2'!$E$16,$C$6) -> 58.414772 | AZ8: -
A9: Nợ gốc | C9: =C8-C10 -> 18.414772 | D9: =D8-D10 -> 19.887954 | E9: =E8-E10 -> 21.478991 | F9: =F8-F10 -> 23.19731 | G9: =G8-G10 -> 25.053095 | H9: =H8-H10 -> 27.057342 | I9: =I8-I10 -> 29.22193 | J9: =J8-J10 -> 31.559684 | ... Q9: =Q8-Q10 -> 54.087752 | AZ9: -
A10: Trả lãi | C10: =C7 -> 40 | D10: =D7 -> 38.526818 | E10: =E7 -> 36.935782 | F10: =F7 -> 35.217463 | G10: =G7 -> 33.361678 | H10: =H7 -> 31.35743 | I10: =I7 -> 29.192843 | J10: =J7 -> 26.855089 | ... Q10: =Q7 -> 4.3270202 | AZ10: -
A11: Nợ cuối kỳ | B11: ='Phương án 2'!E13 -> 500 | C11: =C6+C7-C8 -> 481.58523 | D11: =D6+D7-D8 -> 461.69727 | E11: =E6+E7-E8 -> 440.21828 | F11: =F6+F7-F8 -> 417.02097 | G11: =G6+G7-G8 -> 391.96788 | H11: =H6+H7-H8 -> 364.91054 | I11: =I6+I7-I8 -> 335.68861 | J11: =J6+J7-J8 -> 304.12892 | ... Q11: =Q6+Q7-Q8 -> -5.8264504e-13 | AZ11: -
A12: Ngân lưu tài trợ | B12: =-B11 -> -500 | C12: =C8 -> 58.414772 | D12: =D8 -> 58.414772 | E12: =E8 -> 58.414772 | F12: =F8 -> 58.414772 | G12: =G8 -> 58.414772 | H12: =H8 -> 58.414772 | I12: =I8 -> 58.414772 | J12: =J8 -> 58.414772 | ... Q12: =Q8 -> 58.414772 | AZ12: -
AZ13: -
AZ14: -
A15: CHỈ SỐ GIÁ | AZ15: -
AZ16: -
A17: Năm | B17: 0 | C17: 1 | D17: 2 | E17: 3 | F17: 4 | G17: 5 | H17: 6 | I17: 7 | J17: 8 | K17: 9 | L17: 10 | M17: 11 | N17: 12 | O17: 13 | P17: 14 | Q17: 15 | R17: 16 | S17: 17 | T17: 18 | U17: 19 | V17: 20 | W17: 21 | X17: 22 | Y17: 23 | Z17: 24 | AA17: 25 | AB17: 26 | AC17: 27 | AD17: 28 | AE17: 29 | AF17: 30 | AG17: 31 | AH17: 32 | AI17: 33 | AJ17: 34 | AK17: 35 | AL17: 36 | AM17: 37 | AN17: 38 | AO17: 39 | AP17: 40 | AQ17: 41 | AR17: 42 | AS17: 43 | AT17: 44 | AU17: 45 | AV17: 46 | AW17: 47 | AX17: 48 | AY17: 49 | AZ17: -
A18: Mức giá chung | B18: =(1+'Phương án 2'!$H$6)^'Phân tích phương án 2'!B17 -> 1 | C18: =(1+'Phương án 2'!$H$6)^'Phân tích phương án 2'!C17 -> 1 | D18: =(1+'Phương án 2'!$H$6)^'Phân tích phương án 2'!D17 -> 1 | E18: =(1+'Phương án 2'!$H$6)^'Phân tích phương án 2'!E17 -> 1 | F18: =(1+'Phương án 2'!$H$6)^'Phân tích phương án 2'!F17 -> 1 | G18: =(1+'Phương án 2'!$H$6)^'Phân tích phương án 2'!G17 -> 1 | H18: =(1+'Phương án 2'!$H$6)^'Phân tích phương án 2'!H17 -> 1 | I18: =(1+'Phương án 2'!$H$6)^'Phân tích phương án 2'!I17 -> 1 | ... AY18: =(1+'Phương án 2'!$H$6)^'Phân tích phương án 2'!AY17 -> 1 | AZ18: -
A19: Giá năng lượng | D19: =(1+('Phương án 2'!$H$6+'Phương án 2'!$B$19))^'Phân tích phương án 2'!B17 -> 1 | E19: =(1+('Phương án 2'!$H$6+'Phương án 2'!$B$19))^'Phân tích phương án 2'!C17 -> 1.01 | F19: =(1+('Phương án 2'!$H$6+'Phương án 2'!$B$19))^'Phân tích phương án 2'!D17 -> 1.0201 | G19: =(1+('Phương án 2'!$H$6+'Phương án 2'!$B$19))^'Phân tích phương án 2'!E17 -> 1.030301 | H19: =(1+('Phương án 2'!$H$6+'Phương án 2'!$B$19))^'Phân tích phương án 2'!F17 -> 1.040604 | I19: =(1+('Phương án 2'!$H$6+'Phương án 2'!$B$19))^'Phân tích phương án 2'!G17 -> 1.0510101 | J19: =(1+('Phương án 2'!$H$6+'Phương án 2'!$B$19))^'Phân tích phương án 2'!H17 -> 1.0615202 | K19: =(1+('Phương án 2'!$H$6+'Phương án 2'!$B$19))^'Phân tích phương án 2'!I17 -> 1.0721354 | ... AA19: =(1+('Phương án 2'!$H$6+'Phương án 2'!$B$19))^'Phân tích phương án 2'!Y17 -> 1.257163 | AB19: =(1+('Phương án 2'!$H$6+'Phương án 2'!$B$20))^'Phân tích phương án 2'!AB17 -> 1 | AC19: =(1+('Phương án 2'!$H$6+'Phương án 2'!$B$20))^'Phân tích phương án 2'!AC17 -> 1 | AD19: =(1+('Phương án 2'!$H$6+'Phương án 2'!$B$20))^'Phân tích phương án 2'!AD17 -> 1 | AE19: =(1+('Phương án 2'!$H$6+'Phương án 2'!$B$20))^'Phân tích phương án 2'!AE17 -> 1 | AF19: =(1+('Phương án 2'!$H$6+'Phương án 2'!$B$20))^'Phân tích phương án 2'!AF17 -> 1 | AG19: =(1+('Phương án 2'!$H$6+'Phương án 2'!$B$20))^'Phân tích phương án 2'!AG17 -> 1 | AH19: =(1+('Phương án 2'!$H$6+'Phương án 2'!$B$20))^'Phân tích phương án 2'!AH17 -> 1 | AI19: =(1+('Phương án 2'!$H$6+'Phương án 2'!$B$20))^'Phân tích phương án 2'!AI17 -> 1 | ... AY19: =(1+('Phương án 2'!$H$6+'Phương án 2'!$B$20))^'Phân tích phương án 2'!AY17 -> 1
AZ20: -
A21: CÔNG SUẤT | AZ21: -
AY22: Đơn vị: ML/a | AZ22: -
A23: Năm | B23: =B17 -> 0 | C23: =C17 -> 1 | D23: =D17 -> 2 | E23: =E17 -> 3 | F23: =F17 -> 4 | G23: =G17 -> 5 | H23: =H17 -> 6 | I23: =I17 -> 7 | ... AY23: =AY17 -> 49 | AZ23: -
A24: Công suất | D24: ='Phương án 2'!$B$12 -> 36000 | E24: ='Phương án 2'!$B$12 -> 36000 | F24: ='Phương án 2'!$B$12 -> 36000 | G24: ='Phương án 2'!$B$12 -> 36000 | H24: ='Phương án 2'!$B$12 -> 36000 | I24: ='Phương án 2'!$B$12 -> 36000 | J24: ='Phương án 2'!$B$13 -> 72000 | K24: ='Phương án 2'!$B$13 -> 72000 | L24: ='Phương án 2'!$B$13 -> 72000 | M24: ='Phương án 2'!$B$13 -> 72000 | N24: ='Phương án 2'!$B$13 -> 72000 | O24: ='Phương án 2'!$B$13 -> 72000 | P24: ='Phương án 2'!$B$14 -> 108000 | Q24: ='Phương án 2'!$B$14 -> 108000 | R24: ='Phương án 2'!$B$14 -> 108000 | S24: ='Phương án 2'!$B$14 -> 108000 | T24: ='Phương án 2'!$B$14 -> 108000 | U24: ='Phương án 2'!$B$14 -> 108000 | V24: ='Phương án 2'!$B$15 -> 144000 | W24: ='Phương án 2'!$B$15 -> 144000 | X24: ='Phương án 2'!$B$15 -> 144000 | Y24: ='Phương án 2'!$B$15 -> 144000 | Z24: ='Phương án 2'!$B$15 -> 144000 | AA24: ='Phương án 2'!$B$15 -> 144000 | AB24: ='Phương án 2'!$B$15 -> 144000 | AC24: ='Phương án 2'!$B$15 -> 144000 | ... AY24: ='Phương án 2'!$B$15 -> 144000 | AZ24: -
AZ25: -
AZ26: -
A27: BÁO CÁO THU NHẬP | AZ27: -
AB28: Giả sử không bán nhà máy cho DWR | AY28: Đơn vị: Triệu $ | AZ28: -
A29: Năm | B29: =B23 -> 0 | C29: =C23 -> 1 | D29: =D23 -> 2 | E29: =E23 -> 3 | F29: =F23 -> 4 | G29: =G23 -> 5 | H29: =H23 -> 6 | I29: =I23 -> 7 | ... AY29: =AY23 -> 49 | AZ29: -
A30: Doanh thu thuần | D30: ='Phương án 2'!$F$60/'Phương án 2'!$H$8*D18 -> 171.81818 | E30: ='Phương án 2'!$F$60/'Phương án 2'!$H$8*E18 -> 171.81818 | F30: ='Phương án 2'!$F$60/'Phương án 2'!$H$8*F18 -> 171.81818 | G30: ='Phương án 2'!$F$60/'Phương án 2'!$H$8*G18 -> 171.81818 | H30: ='Phương án 2'!$F$60/'Phương án 2'!$H$8*H18 -> 171.81818 | I30: ='Phương án 2'!$F$60/'Phương án 2'!$H$8*I18 -> 171.81818 | J30: ='Phương án 2'!$F$61/'Phương án 2'!$H$8*J18 -> 343.63636 | K30: ='Phương án 2'!$F$61/'Phương án 2'!$H$8*K18 -> 343.63636 | L30: ='Phương án 2'!$F$61/'Phương án 2'!$H$8*L18 -> 343.63636 | M30: ='Phương án 2'!$F$61/'Phương án 2'!$H$8*M18 -> 343.63636 | N30: ='Phương án 2'!$F$61/'Phương án 2'!$H$8*N18 -> 343.63636 | O30: ='Phương án 2'!$F$61/'Phương án 2'!$H$8*O18 -> 343.63636 | P30: ='Phương án 2'!$F$62/'Phương án 2'!$H$8*P18 -> 515.45455 | Q30: ='Phương án 2'!$F$62/'Phương án 2'!$H$8*Q18 -> 515.45455 | R30: ='Phương án 2'!$F$62/'Phương án 2'!$H$8*R18 -> 515.45455 | S30: ='Phương án 2'!$F$62/'Phương án 2'!$H$8*S18 -> 515.45455 | T30: ='Phương án 2'!$F$62/'Phương án 2'!$H$8*T18 -> 515.45455 | U30: ='Phương án 2'!$F$62/'Phương án 2'!$H$8*U18 -> 515.45455 | V30: ='Phương án 2'!$F$63/'Phương án 2'!$H$8*V18 -> 687.27273 | W30: ='Phương án 2'!$F$63/'Phương án 2'!$H$8*W18 -> 687.27273 | X30: ='Phương án 2'!$F$63/'Phương án 2'!$H$8*X18 -> 687.27273 | Y30: ='Phương án 2'!$F$63/'Phương án 2'!$H$8*Y18 -> 687.27273 | Z30: ='Phương án 2'!$F$63/'Phương án 2'!$H$8*Z18 -> 687.27273 | AA30: ='Phương án 2'!$F$63/'Phương án 2'!$H$8*AA18 -> 687.27273 | AB30: ='Phương án 2'!$F$63/'Phương án 2'!$H$8*AB18 -> 687.27273 | AC30: ='Phương án 2'!$F$63/'Phương án 2'!$H$8*AC18 -> 687.27273 | ... AY30: ='Phương án 2'!$F$63/'Phương án 2'!$H$8*AY18 -> 687.27273 | AZ30: -
A31: Bán thiết bị khử muối | AA31: ='Phương án 2'!$H$18*AA18 -> 100
AZ32: -
A33: Chi phí cố định | D33: =SUM(D34:D36) -> 20.8 | E33: =SUM(E34:E36) -> 20.86 | F33: =SUM(F34:F36) -> 20.9206 | G33: =SUM(G34:G36) -> 20.981806 | H33: =SUM(H34:H36) -> 21.043624 | I33: =SUM(I34:I36) -> 21.10606 | J33: =SUM(J34:J36) -> 30.791449 | K33: =SUM(K34:K36) -> 30.88409 | ... AY33: =SUM(AY34:AY36) -> 60.509091 | AZ33: -
A34: Lương nhân viên, nhân công | D34: ='Phương án 2'!$E$41*D18 -> 8.8 | E34: ='Phương án 2'!$E$41*E18 -> 8.8 | F34: ='Phương án 2'!$E$41*F18 -> 8.8 | G34: ='Phương án 2'!$E$41*G18 -> 8.8 | H34: ='Phương án 2'!$E$41*H18 -> 8.8 | I34: ='Phương án 2'!$E$41*I18 -> 8.8 | J34: =('Phương án 2'!$E$41+'Phương án 2'!$E$50)*J18 -> 12.8 | K34: =('Phương án 2'!$E$41+'Phương án 2'!$E$50)*K18 -> 12.8 | L34: =('Phương án 2'!$E$41+'Phương án 2'!$E$50)*L18 -> 12.8 | M34: =('Phương án 2'!$E$41+'Phương án 2'!$E$50)*M18 -> 12.8 | N34: =('Phương án 2'!$E$41+'Phương án 2'!$E$50)*N18 -> 12.8 | O34: =('Phương án 2'!$E$41+'Phương án 2'!$E$50)*O18 -> 12.8 | P34: =('Phương án 2'!$E$41*2+'Phương án 2'!$E$50)*P18 -> 21.6 | Q34: =('Phương án 2'!$E$41*2+'Phương án 2'!$E$50)*Q18 -> 21.6 | R34: =('Phương án 2'!$E$41*2+'Phương án 2'!$E$50)*R18 -> 21.6 | S34: =('Phương án 2'!$E$41*2+'Phương án 2'!$E$50)*S18 -> 21.6 | T34: =('Phương án 2'!$E$41*2+'Phương án 2'!$E$50)*T18 -> 21.6 | U34: =('Phương án 2'!$E$41*2+'Phương án 2'!$E$50)*U18 -> 21.6 | V34: =('Phương án 2'!$E$41*2+'Phương án 2'!$E$50*2)*V18 -> 25.6 | W34: =('Phương án 2'!$E$41*2+'Phương án 2'!$E$50*2)*W18 -> 25.6 | X34: =('Phương án 2'!$E$41*2+'Phương án 2'!$E$50*2)*X18 -> 25.6 | Y34: =('Phương án 2'!$E$41*2+'Phương án 2'!$E$50*2)*Y18 -> 25.6 | Z34: =('Phương án 2'!$E$41*2+'Phương án 2'!$E$50*2)*Z18 -> 25.6 | AA34: =('Phương án 2'!$E$41*2+'Phương án 2'!$E$50*2)*AA18 -> 25.6 | AB34: =('Phương án 2'!$E$41*2+'Phương án 2'!$E$50*2)*AB18 -> 25.6 | AC34: =('Phương án 2'!$E$41*2+'Phương án 2'!$E$50*2)*AC18 -> 25.6 | ... AY34: =('Phương án 2'!$E$41*2+'Phương án 2'!$E$50*2)*AY18 -> 25.6 | AZ34: -
A35: Năng lượng | D35: ='Phương án 2'!$E$42*D19 -> 6 | E35: ='Phương án 2'!$E$42*E19 -> 6.06 | F35: ='Phương án 2'!$E$42*F19 -> 6.1206 | G35: ='Phương án 2'!$E$42*G19 -> 6.181806 | H35: ='Phương án 2'!$E$42*H19 -> 6.2436241 | I35: ='Phương án 2'!$E$42*I19 -> 6.3060603 | J35: =('Phương án 2'!$E$42+'Phương án 2'!$E$51)*J19 -> 9.2641759 | K35: =('Phương án 2'!$E$42+'Phương án 2'!$E$51)*K19 -> 9.3568176 | L35: =('Phương án 2'!$E$42+'Phương án 2'!$E$51)*L19 -> 9.4503858 | M35: =('Phương án 2'!$E$42+'Phương án 2'!$E$51)*M19 -> 9.5448897 | N35: =('Phương án 2'!$E$42+'Phương án 2'!$E$51)*N19 -> 9.6403385 | O35: =('Phương án 2'!$E$42+'Phương án 2'!$E$51)*O19 -> 9.7367419 | P35: =('Phương án 2'!$E$42*2+'Phương án 2'!$E$51)*P19 -> 16.59506 | Q35: =('Phương án 2'!$E$42*2+'Phương án 2'!$E$51)*Q19 -> 16.76101 | R35: =('Phương án 2'!$E$42*2+'Phương án 2'!$E$51)*R19 -> 16.92862 | S35: =('Phương án 2'!$E$42*2+'Phương án 2'!$E$51)*S19 -> 17.097906 | T35: =('Phương án 2'!$E$42*2+'Phương án 2'!$E$51)*T19 -> 17.268885 | U35: =('Phương án 2'!$E$42*2+'Phương án 2'!$E$51)*U19 -> 17.441574 | V35: =('Phương án 2'!$E$42*2+'Phương án 2'!$E$51*2)*V19 -> 20.87821 | W35: =('Phương án 2'!$E$42*2+'Phương án 2'!$E$51*2)*W19 -> 21.086993 | X35: =('Phương án 2'!$E$42*2+'Phương án 2'!$E$51*2)*X19 -> 21.297863 | Y35: =('Phương án 2'!$E$42*2+'Phương án 2'!$E$51*2)*Y19 -> 21.510841 | Z35: =('Phương án 2'!$E$42*2+'Phương án 2'!$E$51*2)*Z19 -> 21.72595 | AA35: =('Phương án 2'!$E$42*2+'Phương án 2'!$E$51*2)*AA19 -> 21.943209 | AB35: =('Phương án 2'!$E$42*2+'Phương án 2'!$E$51*2)*AB19 -> 17.454545 | AC35: =('Phương án 2'!$E$42*2+'Phương án 2'!$E$51*2)*AC19 -> 17.454545 | ... AY35: =('Phương án 2'!$E$42*2+'Phương án 2'!$E$51*2)*AY19 -> 17.454545 | AZ35: -
A36: Nguyên vật liệu | D36: ='Phương án 2'!$E$43*D18 -> 6 | E36: ='Phương án 2'!$E$43*E18 -> 6 | F36: ='Phương án 2'!$E$43*F18 -> 6 | G36: ='Phương án 2'!$E$43*G18 -> 6 | H36: ='Phương án 2'!$E$43*H18 -> 6 | I36: ='Phương án 2'!$E$43*I18 -> 6 | J36: =('Phương án 2'!$E$43+'Phương án 2'!$E$52)*J18 -> 8.7272727 | K36: =('Phương án 2'!$E$43+'Phương án 2'!$E$52)*K18 -> 8.7272727 | L36: =('Phương án 2'!$E$43+'Phương án 2'!$E$52)*L18 -> 8.7272727 | M36: =('Phương án 2'!$E$43+'Phương án 2'!$E$52)*M18 -> 8.7272727 | N36: =('Phương án 2'!$E$43+'Phương án 2'!$E$52)*N18 -> 8.7272727 | O36: =('Phương án 2'!$E$43+'Phương án 2'!$E$52)*O18 -> 8.7272727 | P36: =('Phương án 2'!$E$43*2+'Phương án 2'!$E$52)*P18 -> 14.727273 | Q36: =('Phương án 2'!$E$43*2+'Phương án 2'!$E$52)*Q18 -> 14.727273 | R36: =('Phương án 2'!$E$43*2+'Phương án 2'!$E$52)*R18 -> 14.727273 | S36: =('Phương án 2'!$E$43*2+'Phương án 2'!$E$52)*S18 -> 14.727273 | T36: =('Phương án 2'!$E$43*2+'Phương án 2'!$E$52)*T18 -> 14.727273 | U36: =('Phương án 2'!$E$43*2+'Phương án 2'!$E$52)*U18 -> 14.727273 | V36: =('Phương án 2'!$E$43*2+'Phương án 2'!$E$52*2)*V18 -> 17.454545 | W36: =('Phương án 2'!$E$43*2+'Phương án 2'!$E$52*2)*W18 -> 17.454545 | X36: =('Phương án 2'!$E$43*2+'Phương án 2'!$E$52*2)*X18 -> 17.454545 | Y36: =('Phương án 2'!$E$43*2+'Phương án 2'!$E$52*2)*Y18 -> 17.454545 | Z36: =('Phương án 2'!$E$43*2+'Phương án 2'!$E$52*2)*Z18 -> 17.454545 | AA36: =('Phương án 2'!$E$43*2+'Phương án 2'!$E$52*2)*AA18 -> 17.454545 | AB36: =('Phương án 2'!$E$43*2+'Phương án 2'!$E$52*2)*AB18 -> 17.454545 | AC36: =('Phương án 2'!$E$43*2+'Phương án 2'!$E$52*2)*AC18 -> 17.454545 | ... AY36: =('Phương án 2'!$E$43*2+'Phương án 2'!$E$52*2)*AY18 -> 17.454545 | AZ36: -
A37: Chi phí biến đổi | D37: =SUM(D38:D40) -> 11.912727 | E37: =SUM(E38:E40) -> 11.947091 | F37: =SUM(F38:F40) -> 11.981798 | G37: =SUM(G38:G40) -> 12.016853 | H37: =SUM(H38:H40) -> 12.052257 | I37: =SUM(I38:I40) -> 12.088016 | J37: =SUM(J38:J40) -> 24.248266 | K37: =SUM(K38:K40) -> 24.321221 | ... AY37: =SUM(AY38:AY40) -> 47.650909 | AZ37: -
A38: Lương nhân viên, nhân công | D38: =('Phương án 2'!$E$45)*'Phương án 2'!$B$12/'Phương án 2'!$H$8*'Phân tích phương án 2'!D18 -> 5.04 | E38: =('Phương án 2'!$E$45)*'Phương án 2'!$B$12/'Phương án 2'!$H$8*'Phân tích phương án 2'!E18 -> 5.04 | F38: =('Phương án 2'!$E$45)*'Phương án 2'!$B$12/'Phương án 2'!$H$8*'Phân tích phương án 2'!F18 -> 5.04 | G38: =('Phương án 2'!$E$45)*'Phương án 2'!$B$12/'Phương án 2'!$H$8*'Phân tích phương án 2'!G18 -> 5.04 | H38: =('Phương án 2'!$E$45)*'Phương án 2'!$B$12/'Phương án 2'!$H$8*'Phân tích phương án 2'!H18 -> 5.04 | I38: =('Phương án 2'!$E$45)*'Phương án 2'!$B$12/'Phương án 2'!$H$8*'Phân tích phương án 2'!I18 -> 5.04 | J38: =('Phương án 2'!$E$45+'Phương án 2'!$E$54)*'Phương án 2'!$B$12/'Phương án 2'!$H$8*'Phân tích phương án 2'!J18 -> 10.08 | K38: =('Phương án 2'!$E$45+'Phương án 2'!$E$54)*'Phương án 2'!$B$12/'Phương án 2'!$H$8*'Phân tích phương án 2'!K18 -> 10.08 | L38: =('Phương án 2'!$E$45+'Phương án 2'!$E$54)*'Phương án 2'!$B$12/'Phương án 2'!$H$8*'Phân tích phương án 2'!L18 -> 10.08 | M38: =('Phương án 2'!$E$45+'Phương án 2'!$E$54)*'Phương án 2'!$B$12/'Phương án 2'!$H$8*'Phân tích phương án 2'!M18 -> 10.08 | N38: =('Phương án 2'!$E$45+'Phương án 2'!$E$54)*'Phương án 2'!$B$12/'Phương án 2'!$H$8*'Phân tích phương án 2'!N18 -> 10.08 | O38: =('Phương án 2'!$E$45+'Phương án 2'!$E$54)*'Phương án 2'!$B$12/'Phương án 2'!$H$8*'Phân tích phương án 2'!O18 -> 10.08 | P38: =('Phương án 2'!$E$45*2+'Phương án 2'!$E$54)*'Phương án 2'!$B$12/'Phương án 2'!$H$8*'Phân tích phương án 2'!P18 -> 15.12 | Q38: =('Phương án 2'!$E$45*2+'Phương án 2'!$E$54)*'Phương án 2'!$B$12/'Phương án 2'!$H$8*'Phân tích phương án 2'!Q18 -> 15.12 | R38: =('Phương án 2'!$E$45*2+'Phương án 2'!$E$54)*'Phương án 2'!$B$12/'Phương án 2'!$H$8*'Phân tích phương án 2'!R18 -> 15.12 | S38: =('Phương án 2'!$E$45*2+'Phương án 2'!$E$54)*'Phương án 2'!$B$12/'Phương án 2'!$H$8*'Phân tích phương án 2'!S18 -> 15.12 | T38: =('Phương án 2'!$E$45*2+'Phương án 2'!$E$54)*'Phương án 2'!$B$12/'Phương án 2'!$H$8*'Phân tích phương án 2'!T18 -> 15.12 | U38: =('Phương án 2'!$E$45*2+'Phương án 2'!$E$54)*'Phương án 2'!$B$12/'Phương án 2'!$H$8*'Phân tích phương án 2'!U18 -> 15.12 | V38: =('Phương án 2'!$E$45*2+'Phương án 2'!$E$54*2)*'Phương án 2'!$B$12/'Phương án 2'!$H$8*'Phân tích phương án 2'!V18 -> 20.16 | W38: =('Phương án 2'!$E$45*2+'Phương án 2'!$E$54*2)*'Phương án 2'!$B$12/'Phương án 2'!$H$8*'Phân tích phương án 2'!W18 -> 20.16 | X38: =('Phương án 2'!$E$45*2+'Phương án 2'!$E$54*2)*'Phương án 2'!$B$12/'Phương án 2'!$H$8*'Phân tích phương án 2'!X18 -> 20.16 | Y38: =('Phương án 2'!$E$45*2+'Phương án 2'!$E$54*2)*'Phương án 2'!$B$12/'Phương án 2'!$H$8*'Phân tích phương án 2'!Y18 -> 20.16 | Z38: =('Phương án 2'!$E$45*2+'Phương án 2'!$E$54*2)*'Phương án 2'!$B$12/'Phương án 2'!$H$8*'Phân tích phương án 2'!Z18 -> 20.16 | AA38: =('Phương án 2'!$E$45*2+'Phương án 2'!$E$54*2)*'Phương án 2'!$B$12/'Phương án 2'!$H$8*'Phân tích phương án 2'!AA18 -> 20.16 | AB38: =('Phương án 2'!$E$45*2+'Phương án 2'!$E$54*2)*'Phương án 2'!$B$12/'Phương án 2'!$H$8*'Phân tích phương án 2'!AB18 -> 20.16 | AC38: =('Phương án 2'!$E$45*2+'Phương án 2'!$E$54*2)*'Phương án 2'!$B$12/'Phương án 2'!$H$8*'Phân tích phương án 2'!AC18 -> 20.16 | ... AY38: =('Phương án 2'!$E$45*2+'Phương án 2'!$E$54*2)*'Phương án 2'!$B$12/'Phương án 2'!$H$8*'Phân tích phương án 2'!AY18 -> 20.16 | AZ38: -
A39: Năng lượng | D39: =('Phương án 2'!$E$46)*'Phương án 2'!$B$12/'Phương án 2'!$H$8*D19 -> 3.4363636 | E39: =('Phương án 2'!$E$46)*'Phương án 2'!$B$12/'Phương án 2'!$H$8*E19 -> 3.4707273 | F39: =('Phương án 2'!$E$46)*'Phương án 2'!$B$12/'Phương án 2'!$H$8*F19 -> 3.5054345 | G39: =('Phương án 2'!$E$46)*'Phương án 2'!$B$12/'Phương án 2'!$H$8*G19 -> 3.5404889 | H39: =('Phương án 2'!$E$46)*'Phương án 2'!$B$12/'Phương án 2'!$H$8*H19 -> 3.5758938 | I39: =('Phương án 2'!$E$46)*'Phương án 2'!$B$12/'Phương án 2'!$H$8*I19 -> 3.6116527 | J39: =('Phương án 2'!$E$46+'Phương án 2'!$E$55)*'Phương án 2'!$B$12/'Phương án 2'!$H$8*J19 -> 7.2955385 | K39: =('Phương án 2'!$E$46+'Phương án 2'!$E$55)*'Phương án 2'!$B$12/'Phương án 2'!$H$8*K19 -> 7.3684939 | L39: =('Phương án 2'!$E$46+'Phương án 2'!$E$55)*'Phương án 2'!$B$12/'Phương án 2'!$H$8*L19 -> 7.4421788 | M39: =('Phương án 2'!$E$46+'Phương án 2'!$E$55)*'Phương án 2'!$B$12/'Phương án 2'!$H$8*M19 -> 7.5166006 | N39: =('Phương án 2'!$E$46+'Phương án 2'!$E$55)*'Phương án 2'!$B$12/'Phương án 2'!$H$8*N19 -> 7.5917666 | O39: =('Phương án 2'!$E$46+'Phương án 2'!$E$55)*'Phương án 2'!$B$12/'Phương án 2'!$H$8*O19 -> 7.6676843 | P39: =('Phương án 2'!$E$46*2+'Phương án 2'!$E$55)*'Phương án 2'!$B$12/'Phương án 2'!$H$8*P19 -> 11.616542 | Q39: =('Phương án 2'!$E$46*2+'Phương án 2'!$E$55)*'Phương án 2'!$B$12/'Phương án 2'!$H$8*Q19 -> 11.732707 | R39: =('Phương án 2'!$E$46*2+'Phương án 2'!$E$55)*'Phương án 2'!$B$12/'Phương án 2'!$H$8*R19 -> 11.850034 | S39: =('Phương án 2'!$E$46*2+'Phương án 2'!$E$55)*'Phương án 2'!$B$12/'Phương án 2'!$H$8*S19 -> 11.968535 | T39: =('Phương án 2'!$E$46*2+'Phương án 2'!$E$55)*'Phương án 2'!$B$12/'Phương án 2'!$H$8*T19 -> 12.08822 | U39: =('Phương án 2'!$E$46*2+'Phương án 2'!$E$55)*'Phương án 2'!$B$12/'Phương án 2'!$H$8*U19 -> 12.209102 | V39: =('Phương án 2'!$E$46*2+'Phương án 2'!$E$55*2)*'Phương án 2'!$B$12/'Phương án 2'!$H$8*V19 -> 16.441591 | W39: =('Phương án 2'!$E$46*2+'Phương án 2'!$E$55*2)*'Phương án 2'!$B$12/'Phương án 2'!$H$8*W19 -> 16.606007 | X39: =('Phương án 2'!$E$46*2+'Phương án 2'!$E$55*2)*'Phương án 2'!$B$12/'Phương án 2'!$H$8*X19 -> 16.772067 | Y39: =('Phương án 2'!$E$46*2+'Phương án 2'!$E$55*2)*'Phương án 2'!$B$12/'Phương án 2'!$H$8*Y19 -> 16.939787 | Z39: =('Phương án 2'!$E$46*2+'Phương án 2'!$E$55*2)*'Phương án 2'!$B$12/'Phương án 2'!$H$8*Z19 -> 17.109185 | AA39: =('Phương án 2'!$E$46*2+'Phương án 2'!$E$55*2)*'Phương án 2'!$B$12/'Phương án 2'!$H$8*AA19 -> 17.280277 | AB39: =('Phương án 2'!$E$46*2+'Phương án 2'!$E$55*2)*'Phương án 2'!$B$12/'Phương án 2'!$H$8*AB19 -> 13.745455 | AC39: =('Phương án 2'!$E$46*2+'Phương án 2'!$E$55*2)*'Phương án 2'!$B$12/'Phương án 2'!$H$8*AC19 -> 13.745455 | ... AY39: =('Phương án 2'!$E$46*2+'Phương án 2'!$E$55*2)*'Phương án 2'!$B$12/'Phương án 2'!$H$8*AY19 -> 13.745455 | AZ39: -
A40: Nguyên vật liệu | D40: =('Phương án 2'!$E$47)*'Phương án 2'!$B$12/'Phương án 2'!$H$8*'Phân tích phương án 2'!D18 -> 3.4363636 | E40: =('Phương án 2'!$E$47)*'Phương án 2'!$B$12/'Phương án 2'!$H$8*'Phân tích phương án 2'!E18 -> 3.4363636 | F40: =('Phương án 2'!$E$47)*'Phương án 2'!$B$12/'Phương án 2'!$H$8*'Phân tích phương án 2'!F18 -> 3.4363636 | G40: =('Phương án 2'!$E$47)*'Phương án 2'!$B$12/'Phương án 2'!$H$8*'Phân tích phương án 2'!G18 -> 3.4363636 | H40: =('Phương án 2'!$E$47)*'Phương án 2'!$B$12/'Phương án 2'!$H$8*'Phân tích phương án 2'!H18 -> 3.4363636 | I40: =('Phương án 2'!$E$47)*'Phương án 2'!$B$12/'Phương án 2'!$H$8*'Phân tích phương án 2'!I18 -> 3.4363636 | J40: =('Phương án 2'!$E$47+'Phương án 2'!$E$56)*'Phương án 2'!$B$12/'Phương án 2'!$H$8*'Phân tích phương án 2'!J18 -> 6.8727273 | K40: =('Phương án 2'!$E$47+'Phương án 2'!$E$56)*'Phương án 2'!$B$12/'Phương án 2'!$H$8*'Phân tích phương án 2'!K18 -> 6.8727273 | L40: =('Phương án 2'!$E$47+'Phương án 2'!$E$56)*'Phương án 2'!$B$12/'Phương án 2'!$H$8*'Phân tích phương án 2'!L18 -> 6.8727273 | M40: =('Phương án 2'!$E$47+'Phương án 2'!$E$56)*'Phương án 2'!$B$12/'Phương án 2'!$H$8*'Phân tích phương án 2'!M18 -> 6.8727273 | N40: =('Phương án 2'!$E$47+'Phương án 2'!$E$56)*'Phương án 2'!$B$12/'Phương án 2'!$H$8*'Phân tích phương án 2'!N18 -> 6.8727273 | O40: =('Phương án 2'!$E$47+'Phương án 2'!$E$56)*'Phương án 2'!$B$12/'Phương án 2'!$H$8*'Phân tích phương án 2'!O18 -> 6.8727273 | P40: =('Phương án 2'!$E$47*2+'Phương án 2'!$E$56)*'Phương án 2'!$B$12/'Phương án 2'!$H$8*'Phân tích phương án 2'!P18 -> 10.309091 | Q40: =('Phương án 2'!$E$47*2+'Phương án 2'!$E$56)*'Phương án 2'!$B$12/'Phương án 2'!$H$8*'Phân tích phương án 2'!Q18 -> 10.309091 | R40: =('Phương án 2'!$E$47*2+'Phương án 2'!$E$56)*'Phương án 2'!$B$12/'Phương án 2'!$H$8*'Phân tích phương án 2'!R18 -> 10.309091 | S40: =('Phương án 2'!$E$47*2+'Phương án 2'!$E$56)*'Phương án 2'!$B$12/'Phương án 2'!$H$8*'Phân tích phương án 2'!S18 -> 10.309091 | T40: =('Phương án 2'!$E$47*2+'Phương án 2'!$E$56)*'Phương án 2'!$B$12/'Phương án 2'!$H$8*'Phân tích phương án 2'!T18 -> 10.309091 | U40: =('Phương án 2'!$E$47*2+'Phương án 2'!$E$56)*'Phương án 2'!$B$12/'Phương án 2'!$H$8*'Phân tích phương án 2'!U18 -> 10.309091 | V40: =('Phương án 2'!$E$47*2+'Phương án 2'!$E$56*2)*'Phương án 2'!$B$12/'Phương án 2'!$H$8*'Phân tích phương án 2'!V18 -> 13.745455 | W40: =('Phương án 2'!$E$47*2+'Phương án 2'!$E$56*2)*'Phương án 2'!$B$12/'Phương án 2'!$H$8*'Phân tích phương án 2'!W18 -> 13.745455 | X40: =('Phương án 2'!$E$47*2+'Phương án 2'!$E$56*2)*'Phương án 2'!$B$12/'Phương án 2'!$H$8*'Phân tích phương án 2'!X18 -> 13.745455 | Y40: =('Phương án 2'!$E$47*2+'Phương án 2'!$E$56*2)*'Phương án 2'!$B$12/'Phương án 2'!$H$8*'Phân tích phương án 2'!Y18 -> 13.745455 | Z40: =('Phương án 2'!$E$47*2+'Phương án 2'!$E$56*2)*'Phương án 2'!$B$12/'Phương án 2'!$H$8*'Phân tích phương án 2'!Z18 -> 13.745455 | AA40: =('Phương án 2'!$E$47*2+'Phương án 2'!$E$56*2)*'Phương án 2'!$B$12/'Phương án 2'!$H$8*'Phân tích phương án 2'!AA18 -> 13.745455 | AB40: =('Phương án 2'!$E$47*2+'Phương án 2'!$E$56*2)*'Phương án 2'!$B$12/'Phương án 2'!$H$8*'Phân tích phương án 2'!AB18 -> 13.745455 | AC40: =('Phương án 2'!$E$47*2+'Phương án 2'!$E$56*2)*'Phương án 2'!$B$12/'Phương án 2'!$H$8*'Phân tích phương án 2'!AC18 -> 13.745455 | ... AY40: =('Phương án 2'!$E$47*2+'Phương án 2'!$E$56*2)*'Phương án 2'!$B$12/'Phương án 2'!$H$8*'Phân tích phương án 2'!AY18 -> 13.745455 | AZ40: -
...

Sheet CB_DATA_
A1: Crystal Ball Data
P2: =_xll.CB.RecalcCounterFN() -> #NAME?
A3: Workbook Variables | B3: Last Var Column | C3: 0
A4: Name:
A5: Value:
A7: Worksheet Data | B7: Last Data Column Used
B8: 7
A10: Sheet Ref
A11: =CB_DATA_!#REF! -> #REF! | D11: ='Phân tích phương án 2'!#REF! -> #REF! | E11: ='Phương án 1'!#REF! -> #REF! | F11: ='Phân tích phương án 1'!#REF! -> #REF! | G11: ='Phương án 2'!#REF! -> #REF!
A13: Sheet Guid
A14: 1b98f190-3b3f-4dea-abd6-770101860c78 | D14: c8058413-c379-4623-aa28-a8a5f0ccfd18 | E14: c344aa33-a1c8-496c-8060-abfebccf436d | F14: e279ecc4-4e25-4a2c-9bdc-6b232e9deb8b | G14: a930a620-0c81-47cc-86a9-b89af5fd6c9c
A16: Deleted sheet count
A19: Last row used
A20: 31 | D20: 31 | E20: 31 | F20: 31 | G20: 31
A25: Data blocks
A26: CB_Block_0 | D26: CB_Block_7.0.0.0:1 | E26: CB_Block_7.0.0.0:1 | F26: CB_Block_7.0.0.0:1 | G26: CB_Block_7.0.0.0:1
